Workbook

Sheet Финал
A2: Результаты Турнира "5 Элемент", 2 раунд. Финал (12-13.10.2024)
A4: Место | B4: Игровой ник | C4: Сумма баллов | D4: Количество побед | E4: Баллы за победу | F4: Доп. Баллы (с ЛХ и Ci) | G4: Игра 1 | M4: Игра 2 | S4: Игра 3 | Y4: Игра 4 | AE4: Игра 5 | AK4: Игра 6 | AQ4: Игра 7 | AW4: Игра 8 | BC4: Игра 9 | BI4: Игра 10 | BO4: Игра 11 | BU4: Игра 12 | CA4: Игра 13 | CG4: Игра 14 | CM4: Дисциплинарный штраф
G5: Роль | H5: Баллы за победу | I5: Баллы от ведущих | J5: Инфо | K5: ЛХ | L5: Ci | M5: Роль | N5: Баллы за победу | O5: Баллы от ведущих | P5: Инфо | Q5: ЛХ | R5: Ci | S5: Роль | T5: Баллы за победу | U5: Баллы от ведущих | V5: Инфо | W5: ЛХ | X5: Ci | Y5: Роль | Z5: Баллы за победу | AA5: Баллы от ведущих | AB5: Инфо | AC5: ЛХ | AD5: Ci | AE5: Роль | AF5: Баллы за победу | AG5: Баллы от ведущих | AH5: Инфо | AI5: ЛХ | AJ5: Ci | AK5: Роль | AL5: Баллы за победу | AM5: Баллы от ведущих | AN5: Инфо | AO5: ЛХ | AP5: Ci | AQ5: Роль | AR5: Баллы за победу | AS5: Баллы от ведущих | AT5: Инфо | AU5: ЛХ | AV5: Ci | AW5: Роль | AX5: Баллы за победу | AY5: Баллы от ведущих | AZ5: Инфо | BA5: ЛХ | BB5: Ci | BC5: Роль | BD5: Баллы за победу | BE5: Баллы от ведущих | BF5: Инфо | BG5: ЛХ | BH5: Ci | BI5: Роль | BJ5: Баллы за победу | BK5: Баллы от ведущих | BL5: Инфо | BM5: ЛХ | BN5: Ci | BO5: Роль | BP5: Баллы за победу | BQ5: Баллы от ведущих | BR5: Инфо | BS5: ЛХ | BT5: Ci | BU5: Роль | BV5: Баллы за победу | BW5: Баллы от ведущих | BX5: Инфо | BY5: ЛХ | BZ5: Ci | CA5: Роль | CB5: Баллы за победу | CC5: Баллы от ведущих | CD5: Инфо | CE5: ЛХ | CF5: Ci | CG5: Роль | CH5: Баллы за победу | CI5: Баллы от ведущих | CJ5: Инфо | CK5: ЛХ | CL5: Ci
A6: 1 | B6: Тихий Закат | C6: =SUM(H6:CM6) -> 54 | D6: =E6/2.5 -> 5 | E6: =SUM(H6+N6+T6+Z6+AF6+AL6+AR6+AX6+BD6+BJ6+BP6+BV6+CB6+CH6) -> 12.5 | F6: =C6-E6 -> 41.5 | G6: Мирный | H6: 2.5 | I6: 3 | J6: ПУ | M6: Мирный | O6: 3.25 | S6: Шериф | U6: 1.5 | Y6: Мирный | AA6: 4 | AE6: Мирный | AG6: 3.5 | AK6: Шериф | AM6: 2.75 | AN6: ПУ | AP6: 0.5 | AQ6: Мирный | AR6: 2.5 | AS6: 4.75 | AW6: Мирный | AY6: 1.75 | BC6: Мирный | BE6: 1.25 | BI6: Мирный | BK6: 1.5 | BO6: Мирный | BP6: 2.5 | BQ6: 2.25 | BR6: ПУ | BT6: 1 | BU6: Мафия | BV6: 2.5 | BW6: 3.25 | CA6: Мирный | CC6: 3 | CG6: Шериф | CH6: 2.5 | CI6: 4.25
A7: 2 | B7: Чешир | C7: =SUM(H7:CM7) -> 48.5 | D7: =E7/2.5 -> 5 | E7: =SUM(H7+N7+T7+Z7+AF7+AL7+AR7+AX7+BD7+BJ7+BP7+BV7+CB7+CH7) -> 12.5 | F7: =C7-E7 -> 36 | G7: Шериф | H7: 2.5 | I7: 3.5 | M7: Шериф | O7: 1.75 | S7: Мафия | T7: 2.5 | U7: 3.75 | Y7: Мирный | AA7: 3 | AE7: Мирный | AG7: 2.75 | AK7: Мирный | AM7: 3.75 | AN7: У/Проигрыш | AQ7: Мафия | AS7: 0 | AW7: Мирный | AY7: 1.75 | BC7: Мирный | BE7: 1.5 | BI7: Мафия | BJ7: 2.5 | BK7: 3.5 | BO7: Дон | BQ7: 2.25 | BU7: Дон | BV7: 2.5 | BW7: 3.25 | CA7: Дон | CB7: 2.5 | CC7: 3.25 | CG7: Мафия | CI7: 2
A8: 3 | B8: Зверюга | C8: =SUM(H8:CM8) -> 55 | D8: =E8/2.5 -> 6 | E8: =SUM(H8+N8+T8+Z8+AF8+AL8+AR8+AX8+BD8+BJ8+BP8+BV8+CB8+CH8) -> 15 | F8: =C8-E8 -> 40 | G8: Мафия | I8: 2.25 | M8: Дон | N8: 2.5 | O8: 3.25 | S8: Мирный | U8: 3.25 | V8: ПУ | W8: 0.5 | Y8: Мафия | Z8: 2.5 | AA8: 3.5 | AE8: Шериф | AG8: 3.25 | AH8: ПУ | AI8: 0.5 | AJ8: 0.5 | AK8: Мафия | AL8: 2.5 | AM8: 3.25 | AQ8: Дон | AS8: 2 | AW8: Мирный | AY8: 1.75 | BC8: Мирный | BE8: 2 | BI8: Мирный | BK8: 1.75 | BO8: Мирный | BP8: 2.5 | BQ8: 3 | BR8: У/Победа | BU8: Мафия | BV8: 2.5 | BW8: 3.75 | CA8: Мирный | CC8: 2 | CD8: У/Проигрыш | CG8: Мирный | CH8: 2.5 | CI8: 3.5
A9: 4 | B9: Махинатор | C9: =SUM(H9:CM9) -> 51.5 | D9: =E9/2.5 -> 6 | E9: =SUM(H9+N9+T9+Z9+AF9+AL9+AR9+AX9+BD9+BJ9+BP9+BV9+CB9+CH9) -> 15 | F9: =C9-E9 -> 36.5 | G9: Мирный | H9: 2.5 | I9: 4 | M9: Мафия | N9: 2.5 | O9: 2.5 | S9: Мирный | U9: 2.25 | Y9: Мирный | AA9: 2.25 | AB9: ПУ | AC9: 0.5 | AE9: Мафия | AF9: 2.5 | AG9: 2.5 | AK9: Мафия | AL9: 2.5 | AM9: 3 | AQ9: Мафия | AS9: 2.5 | AW9: Мирный | AY9: 1.75 | BC9: Мафия | BD9: 2.5 | BE9: 3.5 | BI9: Мирный | BK9: 2 | BO9: Мафия | BQ9: 2.75 | BR9: У/Проигрыш | BU9: Мирный | BW9: 1 | CA9: Мирный | CC9: 2 | CG9: Мирный | CH9: 2.5 | CI9: 4
A10: 5 | B10: NME | C10: =SUM(H10:CM10) -> 49.75 | D10: =E10/2.5 -> 5 | E10: =SUM(H10+N10+T10+Z10+AF10+AL10+AR10+AX10+BD10+BJ10+BP10+BV10+CB10+CH10) -> 12.5 | F10: =C10-E10 -> 37.25 | G10: Мафия | I10: 2 | J10: У/Проигрыш | M10: Мафия | N10: 2.5 | O10: 4 | P10: У/Победа | S10: Дон | T10: 2.5 | U10: 2 | V10: У/Победа | Y10: Мирный | AA10: 2.75 | AE10: Мирный | AG10: 3 | AH10: У/Проигрыш | AK10: Дон | AL10: 2.5 | AM10: 3.75 | AN10: У/Победа | AQ10: Мирный | AR10: 2.5 | AS10: 2.5 | AW10: Дон | AX10: 2.5 | AY10: 3.75 | BC10: Мирный | BE10: 2.25 | BF10: ПУ | BI10: Шериф | BK10: 1.75 | BL10: ПУ | BN10: 0.5 | BO10: Мафия | BQ10: 2 | BU10: Мирный | BW10: 3.5 | CA10: Мирный | CC10: 1.5 | CG10: Мафия | CI10: 2
A11: 6 | B11: Curly | C11: =SUM(H11:CM11) -> 50.25 | D11: =E11/2.5 -> 5 | E11: =SUM(H11+N11+T11+Z11+AF11+AL11+AR11+AX11+BD11+BJ11+BP11+BV11+CB11+CH11) -> 12.5 | F11: =C11-E11 -> 37.75 | G11: Мирный | H11: 2.5 | I11: 3.25 | M11: Мирный | O11: 2.25 | S11: Мирный | U11: 2 | V11: У/Проигрыш | Y11: Мирный | AA11: 1.5 | AE11: Мирный | AG11: 2.5 | AK11: Мирный | AM11: 3.25 | AQ11: Мирный | AR11: 2.5 | AS11: 3 | AW11: Шериф | AY11: 2.25 | AZ11: ПУ | BC11: Мирный | BE11: 2 | BI11: Мафия | BJ11: 2.5 | BK11: 3 | BO11: Мирный | BP11: 2.5 | BQ11: 3.75 | BU11: Мирный | BW11: 2.5 | CA11: Шериф | CC11: 3.25 | CG11: Мирный | CH11: 2.5 | CI11: 3.25
A12: 7 | B12: Дракарис | C12: =SUM(H12:CM12) -> 55 | D12: =E12/2.5 -> 6 | E12: =SUM(H12+N12+T12+Z12+AF12+AL12+AR12+AX12+BD12+BJ12+BP12+BV12+CB12+CH12) -> 15 | F12: =C12-E12 -> 40 | G12: Мирный | H12: 2.5 | I12: 2.5 | M12: Мирный | O12: 2.25 | S12: Мирный | U12: 2 | Y12: Дон | Z12: 2.5 | AA12: 3.5 | AE12: Мирный | AG12: 3.25 | AK12: Мирный | AM12: 2.25 | AQ12: Шериф | AR12: 2.5 | AS12: 3.25 | AW12: Мирный | AY12: 1.75 | BC12: Дон | BD12: 2.5 | BE12: 4 | BI12: Мирный | BK12: 3.75 | BO12: Шериф | BP12: 2.5 | BQ12: 3.5 | BR12: У/Победа | BU12: Шериф | BW12: 2 | CA12: Мирный | CC12: 2.5 | CD12: ПУ | CG12: Мирный | CH12: 2.5 | CI12: 3.5
A13: 8 | B13: Никнейм | C13: =SUM(H13:CM13) -> 51 | D13: =E13/2.5 -> 5 | E13: =SUM(H13+N13+T13+Z13+AF13+AL13+AR13+AX13+BD13+BJ13+BP13+BV13+CB13+CH13) -> 12.5 | F13: =C13-E13 -> 38.5 | G13: Мирный | H13: 2.5 | I13: 4.25 | J13: У/Победа | M13: Мирный | O13: 1.5 | P13: У/Проигрыш | S13: Мирный | U13: 2.75 | Y13: Шериф | AA13: 3 | AE13: Мирный | AG13: 1.5 | AH13: У/Проигрыш | AK13: Мирный | AM13: 3.5 | AQ13: Мирный | AR13: 2.5 | AS13: 2.75 | AW13: Мирный | AY13: 1.75 | BC13: Мафия | BD13: 2.5 | BE13: 3.75 | BI13: Мирный | BK13: 1.75 | BO13: Мирный | BP13: 2.5 | BQ13: 1.75 | BU13: Мирный | BW13: 2.5 | CA13: Мирный | CC13: 3.25 | CD13: У/Проигрыш | CG13: Мирный | CH13: 2.5 | CI13: 4.5
A14: 9 | B14: UFO | C14: =SUM(H14:CM14) -> 52.25 | D14: =E14/2.5 -> 6 | E14: =SUM(H14+N14+T14+Z14+AF14+AL14+AR14+AX14+BD14+BJ14+BP14+BV14+CB14+CH14) -> 15 | F14: =C14-E14 -> 37.25 | G14: Мирный | H14: 2.5 | I14: 3.25 | J14: У/Победа | M14: Мирный | O14: 1.25 | P14: У/Проигрыш | S14: Мирный | U14: 2 | V14: У/Проигрыш | Y14: Мирный | AA14: 2 | AE14: Мафия | AF14: 2.5 | AG14: 3.5 | AH14: У/Победа | AK14: Мирный | AM14: 1.75 | AN14: У/Проигрыш | AQ14: Мирный | AR14: 2.5 | AS14: 3 | AW14: Мафия | AX14: 2.5 | AY14: 3.75 | BC14: Мирный | BE14: 2 | BI14: Мирный | BK14: 3 | BO14: Мирный | BP14: 2.5 | BQ14: 3.25 | BU14: Мирный | BW14: 3.25 | CA14: Мафия | CB14: 2.5 | CC14: 3.75 | CD14: У/Победа | CG14: Дон | CI14: 1.5
A15: 10 | B15: Наполеон | C15: =SUM(H15:CM15) -> 69.5 | D15: =E15/2.5 -> 9 | E15: =SUM(H15+N15+T15+Z15+AF15+AL15+AR15+AX15+BD15+BJ15+BP15+BV15+CB15+CH15) -> 22.5 | F15: =C15-E15 -> 47 | G15: Дон | I15: 2.5 | M15: Мирный | O15: 2.75 | P15: ПУ | Q15: 0.5 | S15: Мафия | T15: 2.5 | U15: 3.75 | Y15: Мафия | Z15: 2.5 | AA15: 3.75 | AE15: Дон | AF15: 2.5 | AG15: 3.25 | AK15: Мирный | AM15: 4 | AQ15: Мирный | AR15: 2.5 | AS15: 2.5 | AT15: ПУ | AV15: 0.5 | AW15: Мафия | AX15: 2.5 | AY15: 3.75 | BC15: Шериф | BE15: 1.5 | BI15: Дон | BJ15: 2.5 | BK15: 3 | BO15: Мирный | BP15: 2.5 | BQ15: 4 | BU15: Мирный | BW15: 2.75 | BX15: ПУ | BZ15: 1 | CA15: Мафия | CB15: 2.5 | CC15: 2.5 | CG15: Мирный | CH15: 2.5 | CI15: 3 | CJ15: ПУ | CK15: 0.5 | CL15: 1.5
A16: Штраф | M16: 56 мин | S16: 60 мин | Y16: 48 мин | AE16: 55 мин | AK16: 47 мин | AQ16: 48 мин
A17: Мафия
A18: Шериф | G18: Победа города в угадайке | M18: Победа мафии 1в1 | S18: Победа мафии 1в1 | Y18: Победа мафии 2в2 | AE18: Победа мафии 1в1 | AK18: Победа мафии 1в1 | AQ18: Победа города на круг при пятерых | AW18: Победа мафии 2в2 | BC18: Победа мафии 2в2 | BI18: Победа мафии 2в2 | BO18: Победа города в угадайке | BU18: Победа мафии 3в3 | CA18: Победа мафии 1в1 | CG18: Сухая победа города
A19: Дон
A20: ПУ
A21: Судья | B21: Yesterday
A22: Линейный | B22: BonAqua
A24: Игра | B24: Игровой Ник | C24: Вид штрафа | D24: Штрафной балл
A26: 2 | B26: Махинатор | C26: Удаление | D26: 1 | E26: {=sort(B6:C15,2,FALSE())} -> #NAME? | F26: #NAME?
A27: 7 | B27: Чешир | C27: Удаление | D27: 2.5 | E27: #NAME? | F27: #NAME?
A28: 10 | B28: Зверюга | C28: Желтая карточка | D28: 0 | E28: #NAME? | F28: #NAME?
A29: 13 | B29: Curly | C29: Желтая карточка | D29: 0 | E29: #NAME? | F29: #NAME?
E30: #NAME? | F30: #NAME?
E31: #NAME? | F31: #NAME?
E32: #NAME? | F32: #NAME?
E33: #NAME? | F33: #NAME?
E34: #NAME? | F34: #NAME?
E35: #NAME? | F35: #NAME?

Sheet 2 Полуфинал
A2: Результаты Турнира "5 Элемент", 1 раунд. Второй Полуфинал (06.10.2024)
A4: Место | B4: Игровой ник | C4: Сумма баллов | D4: Количество побед | E4: Баллы за победу | F4: Доп. Баллы (с ЛХ и Ci) | G4: Игра 1 | M4: Игра 2 | S4: Игра 3 | Y4: Игра 4 | AE4: Игра 5 | AK4: Игра 6 | AQ4: Игра 7 | AW4: Игра 8 | BC4: Дисциплинарный штраф
G5: Роль | H5: Баллы за победу | I5: Баллы от ведущих | J5: Инфо | K5: ЛХ | L5: Ci | M5: Роль | N5: Баллы за победу | O5: Баллы от ведущих | P5: Инфо | Q5: ЛХ | R5: Ci | S5: Роль | T5: Баллы за победу | U5: Баллы от ведущих | V5: Инфо | W5: ЛХ | X5: Ci | Y5: Роль | Z5: Баллы за победу | AA5: Баллы от ведущих | AB5: Инфо | AC5: ЛХ | AD5: Ci | AE5: Роль | AF5: Баллы за победу | AG5: Баллы от ведущих | AH5: Инфо | AI5: ЛХ | AJ5: Ci | AK5: Роль | AL5: Баллы за победу | AM5: Баллы от ведущих | AN5: Инфо | AO5: ЛХ | AP5: Ci | AQ5: Роль | AR5: Баллы за победу | AS5: Баллы от ведущих | AT5: Инфо | AU5: ЛХ | AV5: Ci | AW5: Роль | AX5: Баллы за победу | AY5: Баллы от ведущих | AZ5: Инфо | BA5: ЛХ | BB5: Ci
A6: 1 | B6: Армен 24 | C6: =SUM(H6:BC6) -> 32 | D6: =E6/2.5 -> 4 | E6: =SUM(H6+N6+T6+Z6+AF6+AL6+AR6+AX6) -> 10 | F6: =C6-E6-BC6 -> 22 | G6: Дон | I6: 2.75 | M6: Мирный | N6: 2.5 | O6: 2 | P6: ПУ | R6: 0.5 | S6: Мирный | U6: 1.75 | Y6: Мирный | AA6: 2 | AE6: Мирный | AF6: 2.5 | AG6: 4 | AK6: Мирный | AL6: 2.5 | AM6: 3.75 | AQ6: Дон | AR6: 2.5 | AS6: 3.25 | AW6: Мирный | AY6: 2
A7: 2 | B7: Наполеон | C7: =SUM(H7:BC7) -> 34.5 | D7: =E7/2.5 -> 4 | E7: =SUM(H7+N7+T7+Z7+AF7+AL7+AR7+AX7) -> 10 | F7: =C7-E7-BC7 -> 24.5 | G7: Мафия | I7: 2.25 | M7: Мирный | N7: 2.5 | O7: 3 | S7: Шериф | U7: 2 | Y7: Мирный | AA7: 3 | AE7: Мирный | AF7: 2.5 | AG7: 4.5 | AK7: Мафия | AM7: 2.75 | AN7: У/Проигрыш | AQ7: Мафия | AR7: 2.5 | AS7: 3 | AW7: Мафия | AX7: 2.5 | AY7: 4 | AZ7: У/Победа
A8: 3 | B8: Мона | C8: =SUM(H8:BC8) -> 27.25 | D8: =E8/2.5 -> 3 | E8: =SUM(H8+N8+T8+Z8+AF8+AL8+AR8+AX8) -> 7.5 | F8: =C8-E8-BC8 -> 19.75 | G8: Мирный | H8: 2.5 | I8: 3 | J8: У/Победа | M8: Дон | O8: 2 | S8: Мирный | U8: 2 | Y8: Мирный | AA8: 2.25 | AE8: Мирный | AF8: 2.5 | AG8: 2.5 | AK8: Мирный | AL8: 2.5 | AM8: 2.5 | AN8: ПУ | AO8: 0.5 | AP8: 0.5 | AQ8: Мирный | AS8: 2 | AT8: У/Проигрыш | AW8: Шериф | AY8: 2.5
A9: 4 | B9: UFO | C9: =SUM(H9:BC9) -> 34.75 | D9: =E9/2.5 -> 5 | E9: =SUM(H9+N9+T9+Z9+AF9+AL9+AR9+AX9) -> 12.5 | F9: =C9-E9-BC9 -> 22.25 | G9: Шериф | H9: 2.5 | I9: 2.5 | M9: Мирный | N9: 2.5 | O9: 3 | S9: Мафия | T9: 2.5 | U9: 3.75 | Y9: Мафия | Z9: 2.5 | AA9: 3.25 | AE9: Мафия | AG9: 2.5 | AK9: Шериф | AL9: 2.5 | AM9: 3.25 | AQ9: Шериф | AS9: 2.5 | AW9: Мирный | AY9: 1.5 | AZ9: У/Проигрыш
A10: 5 | B10: Админ | C10: =SUM(H10:BC10) -> 32.25 | D10: =E10/2.5 -> 4 | E10: =SUM(H10+N10+T10+Z10+AF10+AL10+AR10+AX10) -> 10 | F10: =C10-E10-BC10 -> 22.25 | G10: Мафия | I10: 2.5 | J10: У/Проигрыш | M10: Мирный | N10: 2.5 | O10: 3.25 | S10: Мирный | U10: 2.25 | V10: ПУ | X10: 0.5 | Y10: Мафия | Z10: 2.5 | AA10: 3.25 | AE10: Мафия | AG10: 2 | AK10: Мирный | AL10: 2.5 | AM10: 3.75 | AN10: У/Победа | AQ10: Мирный | AS10: 1.75 | AW10: Мафия | AX10: 2.5 | AY10: 3
A11: 6 | B11: Curly | C11: =SUM(H11:BC11) -> 37 | D11: =E11/2.5 -> 5 | E11: =SUM(H11+N11+T11+Z11+AF11+AL11+AR11+AX11) -> 12.5 | F11: =C11-E11-BC11 -> 24.5 | G11: Мирный | H11: 2.5 | I11: 3 | J11: У/Победа | M11: Мирный | N11: 2.5 | O11: 3.25 | S11: Дон | T11: 2.5 | U11: 4 | Y11: Мирный | AA11: 2.5 | AB11: ПУ | AC11: 0.5 | AD11: 0.5 | AE11: Мирный | AF11: 2.5 | AG11: 2.5 | AK11: Мафия | AM11: 2.25 | AQ11: Мафия | AR11: 2.5 | AS11: 4 | AT11: У/Победа | AW11: Мирный | AY11: 2
A12: 7 | B12: Дракарис | C12: =SUM(H12:BC12) -> 36.5 | D12: =E12/2.5 -> 5 | E12: =SUM(H12+N12+T12+Z12+AF12+AL12+AR12+AX12) -> 12.5 | F12: =C12-E12-BC12 -> 24 | G12: Мирный | H12: 2.5 | I12: 2.75 | M12: Шериф | N12: 2.5 | O12: 3.75 | S12: Мафия | T12: 2.5 | U12: 2.5 | Y12: Шериф | AA12: 2.5 | AE12: Мирный | AF12: 2.5 | AG12: 2.75 | AH12: ПУ | AI12: 0.5 | AJ12: 0.5 | AK12: Мирный | AL12: 2.5 | AM12: 3.25 | AQ12: Мирный | AS12: 3 | AW12: Мирный | AY12: 2.5
A13: 8 | B13: Луна | C13: =SUM(H13:BC13) -> 26.25 | D13: =E13/2.5 -> 2 | E13: =SUM(H13+N13+T13+Z13+AF13+AL13+AR13+AX13) -> 5 | F13: =C13-E13-BC13 -> 21.25 | G13: Мирный | H13: 2.5 | I13: 4.25 | M13: Мафия | O13: 2.25 | S13: Мирный | U13: 1.75 | Y13: Мирный | AA13: 3 | AE13: Шериф | AF13: 2.5 | AG13: 2.5 | AK13: Дон | AM13: 2.75 | AQ13: Мирный | AS13: 2.5 | AW13: Мирный | AY13: 1.75 | AZ13: ПУ | BB13: 0.5
A14: 9 | B14: Бастурма | C14: =SUM(H14:BC14) -> 27.75 | D14: =E14/2.5 -> 3 | E14: =SUM(H14+N14+T14+Z14+AF14+AL14+AR14+AX14) -> 7.5 | F14: =C14-E14-BC14 -> 20.25 | G14: Мирный | H14: 2.5 | I14: 3.5 | M14: Мирный | N14: 2.5 | O14: 3 | S14: Мирный | U14: 3.25 | Y14: Мирный | AA14: 2 | AE14: Дон | AG14: 1.5 | AK14: Мирный | AL14: 2.5 | AM14: 3 | AQ14: Мирный | AS14: 2 | AT14: ПУ | AV14: 0.5 | AW14: Мирный | AY14: 1.5 | AZ14: У/Проигрыш
A15: 10 | B15: Никнейм | C15: =SUM(H15:BC15) -> 35 | D15: =E15/2.5 -> 5 | E15: =SUM(H15+N15+T15+Z15+AF15+AL15+AR15+AX15) -> 12.5 | F15: =C15-E15-BC15 -> 22.5 | G15: Мирный | H15: 2.5 | I15: 2 | J15: ПУ | L15: 0.5 | M15: Мафия | O15: 1.75 | S15: Мирный | U15: 2.5 | Y15: Дон | Z15: 2.5 | AA15: 4 | AE15: Мирный | AF15: 2.5 | AG15: 3.75 | AK15: Мирный | AL15: 2.5 | AM15: 2.75 | AN15: У/Победа | AQ15: Мирный | AS15: 2.25 | AT15: У/Проигрыш | AW15: Дон | AX15: 2.5 | AY15: 3
A16: Штраф
A17: Мафия
A18: Шериф | G18: Победа города в угадайке | M18: Сухая победа города | S18: Победа мафии 2в2 | Y18: Победа мафии 2в2 | AE18: Сухая победа города | AK18: Победа города в угадайке | AQ18: Победа мафии 1в1 | AW18: Победа мафии 1в1
A19: Дон
A20: ПУ
A21: Судья | B21: Yesterday
A22: Линейный | B22: -
A24: Игра | B24: Игровой Ник | C24: Вид штрафа | D24: Штрафной балл
E26: {=sort(B6:C15,2,FALSE())} -> #NAME? | F26: #NAME?
E27: #NAME? | F27: #NAME?
E28: #NAME? | F28: #NAME?
E29: #NAME? | F29: #NAME?
E30: #NAME? | F30: #NAME?
E31: #NAME? | F31: #NAME?
E32: #NAME? | F32: #NAME?
E33: #NAME? | F33: #NAME?
E34: #NAME? | F34: #NAME?
E35: #NAME? | F35: #NAME?

Sheet 1 Полуфинал
A2: Результаты Турнира "5 Элемент", 2 раунд. Первый Полуфинал (05.10.2024)
A4: Место | B4: Игровой ник | C4: Сумма баллов | D4: Количество побед | E4: Баллы за победу | F4: Доп. Баллы (с ЛХ и Ci) | G4: Игра 1 | M4: Игра 2 | S4: Игра 3 | Y4: Игра 4 | AE4: Игра 5 | AK4: Игра 6 | AQ4: Игра 7 | AW4: Игра 8 | BC4: Дисциплинарный штраф
G5: Роль | H5: Баллы за победу | I5: Баллы от ведущих | J5: Инфо | K5: ЛХ | L5: Ci | M5: Роль | N5: Баллы за победу | O5: Баллы от ведущих | Q5: ЛХ | R5: Ci | S5: Роль | T5: Баллы за победу | U5: Баллы от ведущих | V5: Инфо | W5: ЛХ | X5: Ci | Y5: Роль | Z5: Баллы за победу | AA5: Баллы от ведущих | AB5: Инфо | AC5: ЛХ | AD5: Ci | AE5: Роль | AF5: Баллы за победу | AG5: Баллы от ведущих | AH5: Инфо | AI5: ЛХ | AJ5: Ci | AK5: Роль | AL5: Баллы за победу | AM5: Баллы от ведущих | AN5: Инфо | AO5: ЛХ | AP5: Ci | AQ5: Роль | AR5: Баллы за победу | AS5: Баллы от ведущих | AT5: Инфо | AU5: ЛХ | AV5: Ci | AW5: Роль | AX5: Баллы за победу | AY5: Баллы от ведущих | AZ5: Инфо | BA5: ЛХ | BB5: Ci
A6: 1 | B6: Coach | C6: =SUM(H6:BC6) -> 30.5 | D6: =E6/2.5 -> 3 | E6: =SUM(H6+N6+T6+Z6+AF6+AL6+AR6+AX6) -> 7.5 | F6: =C6-E6-BC6 -> 23 | G6: Мирный | I6: 2.75 | M6: Шериф | O6: 1.75 | S6: Мафия | U6: 3.25 | Y6: Мафия | AA6: 2.25 | AE6: Мирный | AF6: 2.5 | AG6: 4.25 | AK6: Мирный | AL6: 2.5 | AM6: 2.5 | AQ6: Мирный | AS6: 4 | AW6: Шериф | AX6: 2.5 | AY6: 1.75 | AZ6: ПУ | BB6: 0.5
A7: 2 | B7: Зверюга | C7: =SUM(H7:BC7) -> 35.5 | D7: =E7/2.5 -> 5 | E7: =SUM(H7+N7+T7+Z7+AF7+AL7+AR7+AX7) -> 12.5 | F7: =C7-E7-BC7 -> 23 | G7: Мирный | I7: 1.25 | M7: Мирный | O7: 2.25 | S7: Мафия | U7: 2.75 | Y7: Шериф | Z7: 2.5 | AA7: 4 | AE7: Мирный | AF7: 2.5 | AG7: 4.5 | AH7: У/Победа | AK7: Мирный | AL7: 2.5 | AM7: 3 | AN7: ПУ | AP7: 0.5 | AQ7: Мафия | AR7: 2.5 | AS7: 3.25 | AW7: Мирный | AX7: 2.5 | AY7: 1.5
A8: 3 | B8: Чешир | C8: =SUM(H8:BC8) -> 39 | D8: =E8/2.5 -> 6 | E8: =SUM(H8+N8+T8+Z8+AF8+AL8+AR8+AX8) -> 15 | F8: =C8-E8-BC8 -> 24 | G8: Мирный | I8: 2 | M8: Дон | N8: 2.5 | O8: 3 | S8: Мирный | T8: 2.5 | U8: 3.5 | V8: У/Победа | Y8: Мирный | Z8: 2.5 | AA8: 3.25 | AE8: Мирный | AF8: 2.5 | AG8: 3.25 | AK8: Мирный | AL8: 2.5 | AM8: 2.5 | AQ8: Шериф | AS8: 2.75 | AW8: Мирный | AX8: 2.5 | AY8: 3.75
A9: 4 | B9: NME | C9: =SUM(H9:BC9) -> 33.5 | D9: =E9/2.5 -> 4 | E9: =SUM(H9+N9+T9+Z9+AF9+AL9+AR9+AX9) -> 10 | F9: =C9-E9-BC9 -> 23.5 | G9: Дон | H9: 2.5 | I9: 3.75 | M9: Мирный | O9: 2.5 | R9: 0.5 | S9: Шериф | T9: 2.5 | U9: 2.75 | Y9: Мирный | Z9: 2.5 | AA9: 3.25 | AE9: Мафия | AG9: 3.5 | AH9: У/Проигрыш | AK9: Мафия | AM9: 2.5 | AQ9: Мирный | AS9: 1.25 | AW9: Мирный | AX9: 2.5 | AY9: 3.5
A10: 5 | B10: Still Rise | C10: =SUM(H10:BC10) -> 29.75 | D10: =E10/2.5 -> 4 | E10: =SUM(H10+N10+T10+Z10+AF10+AL10+AR10+AX10) -> 10 | F10: =C10-E10-BC10 -> 19.75 | G10: Мафия | H10: 2.5 | I10: 3 | M10: Мирный | O10: 2.5 | S10: Мирный | T10: 2.5 | U10: 2.5 | V10: У/Победа | Y10: Мирный | Z10: 2.5 | AA10: 3.75 | AE10: Дон | AG10: 1.5 | AK10: Дон | AM10: 1.5 | AQ10: Мафия | AR10: 2.5 | AS10: 3.25 | AW10: Дон | AY10: 1.75
A11: 6 | B11: Махинатор | C11: =SUM(H11:BC11) -> 35 | D11: =E11/2.5 -> 5 | E11: =SUM(H11+N11+T11+Z11+AF11+AL11+AR11+AX11) -> 12.5 | F11: =C11-E11-BC11 -> 22.5 | G11: Мирный | I11: 3.25 | M11: Мирный | O11: 2 | S11: Мирный | T11: 2.5 | U11: 3.25 | V11: У/Победа | Y11: Мирный | Z11: 2.5 | AA11: 4.5 | AE11: Шериф | AF11: 2.5 | AG11: 2 | AK11: Мирный | AL11: 2.5 | AM11: 2.25 | AQ11: Мирный | AS11: 1.5 | AW11: Мирный | AX11: 2.5 | AY11: 3.75
A12: 7 | B12: Cristo | C12: =SUM(H12:BC12) -> 29.75 | D12: =E12/2.5 -> 3 | E12: =SUM(H12+N12+T12+Z12+AF12+AL12+AR12+AX12) -> 7.5 | F12: =C12-E12-BC12 -> 22.25 | G12: Мирный | I12: 3 | J12: ПУ | L12: 0.5 | M12: Мирный | O12: 2.5 | S12: Мирный | T12: 2.5 | U12: 3 | V12: ПУ | W12: 0.5 | X12: 1 | Y12: Дон | AA12: 1 | AE12: Мирный | AF12: 2.5 | AG12: 3 | AK12: Мирный | AL12: 2.5 | AM12: 2 | AQ12: Мирный | AS12: 3.25 | AW12: Мафия | AY12: 2.5
A13: 8 | B13: Арс | C13: =SUM(H13:BC13) -> 30.25 | D13: =E13/2.5 -> 4 | E13: =SUM(H13+N13+T13+Z13+AF13+AL13+AR13+AX13) -> 10 | F13: =C13-E13-BC13 -> 20.25 | G13: Мафия | H13: 2.5 | I13: 3.5 | M13: Мирный | O13: 2.5 | S13: Дон | U13: 1.25 | V13: У/Проигрыш | Y13: Мафия | AA13: 2 | AE13: Мирный | AF13: 2.5 | AG13: 2.25 | AH13: У/Победа | AK13: Мирный | AL13: 2.5 | AM13: 3 | AQ13: Дон | AR13: 2.5 | AS13: 4 | AW13: Мафия | AY13: 1.75
A14: 9 | B14: Тихий Закат | C14: =SUM(H14:BC14) -> 41.5 | D14: =E14/2.5 -> 6 | E14: =SUM(H14+N14+T14+Z14+AF14+AL14+AR14+AX14) -> 15 | F14: =C14-E14-BC14 -> 26.5 | G14: Шериф | I14: 1.75 | M14: Мафия | N14: 2.5 | O14: 3.5 | S14: Мирный | T14: 2.5 | U14: 2.75 | Y14: Мирный | Z14: 2.5 | AA14: 2.5 | AB14: ПУ | AD14: 0.5 | AE14: Мирный | AF14: 2.5 | AG14: 2.5 | AH14: ПУ | AJ14: 1 | AK14: Шериф | AL14: 2.5 | AM14: 5 | AQ14: Мирный | AS14: 1.5 | AT14: ПУ | AV14: 1.5 | AW14: Мирный | AX14: 2.5 | AY14: 4
A15: 10 | B15: Cherry Pick | C15: =SUM(H15:BC15) -> 32 | D15: =E15/2.5 -> 4 | E15: =SUM(H15+N15+T15+Z15+AF15+AL15+AR15+AX15) -> 10 | F15: =C15-E15-BC15 -> 22 | G15: Мирный | I15: 1.75 | M15: Мафия | N15: 2.5 | O15: 3.75 | S15: Мирный | T15: 2.5 | U15: 3.25 | Y15: Мирный | Z15: 2.5 | AA15: 3.25 | AE15: Мафия | AG15: 1.75 | AK15: Мафия | AM15: 2.5 | AQ15: Мирный | AS15: 2 | AW15: Мирный | AX15: 2.5 | AY15: 3.75
A16: Штраф | G16: продолжительность 39 мин | M16: 52 мин | S16: 57 мин | Y16: 38 мин | AE16: 54 мин | AK16: 44 мин | AQ16: 45 мин | AW16: 43 мин
A17: Мафия
A18: Шериф | G18: Победа мафии 3в3 | M18: Победа мафии 1в1 | S18: Победа города в угадайке при четверых | Y18: Сухая победа города | AE18: Победа города в угадайке | AK18: Победа города на круг при шестерых | AQ18: Победа мафии 2в2 | AW18: Победа города на круг при пятерых
A19: Дон
A20: ПУ
A21: Судья | B21: Yesterday
A22: Линейный | B22: -
A24: Игра | B24: Игровой Ник | C24: Вид штрафа | D24: Штрафной балл
A26: 3 | B26: Зверюга | C26: Желтая карточка | D26: 0
A27: 3 | B27: Cherry Pick | C27: Желтая карточка | D27: 0 | E27: {=sort(B6:C15,2,FALSE())} -> #NAME? | F27: #NAME?
A28: 6 | B28: Still Rise | C28: Желтая карточка | D28: 0 | E28: #NAME? | F28: #NAME?
E29: #NAME? | F29: #NAME?
E30: #NAME? | F30: #NAME?
E31: #NAME? | F31: #NAME?
E32: #NAME? | F32: #NAME?
E33: #NAME? | F33: #NAME?
E34: #NAME? | F34: #NAME?
E35: #NAME? | F35: #NAME?
E36: #NAME? | F36: #NAME?

Sheet Статистика Полуфиналы Финал
I1: Количество игр | S1: WINRATE ( % побед) | Z1: Допы (без Ci и ЛХ) | AE1: Средний доп (без Ci и ЛХ)
A3: 1 ПОЛУФИНАЛ
A4: Игрок | B4: Кол-во игр | C4: ЛХ полный | D4: ЛХ двойка | E4: ПУ | F4: Killrate | G4: Победил в угадайке | H4: Проиграл в угадайке | I4: Все красные (М+Ш) игр | J4: Все черные (Д+М) игр | K4: Мафия Побед | L4: Мафия Проигрышей | M4: Шериф Побед | N4: Шериф Проигрышей | O4: Дон Побед | P4: Дон Проигрышей | Q4: Мирный Побед | R4: Мирный Проигрышей | S4: WINRATE общий | T4: Все красные (М+Ш) % побед | U4: Все черные (Д+М) % побед | V4: Мафия: % Побед | W4: Шериф: % Побед | X4: Дон: % Побед | Y4: Мирный: % Побед | Z4: Всего: допы | AA4: Мафия: допы | AB4: Шериф: допы | AC4: Дон: допы | AD4: Мирный: допы | AE4: Общий: ср.доп | AF4: Мафия: ср. доп | AG4: Шериф: ср.доп | AH4: Дон: ср.доп | AI4: Мирный: ср.доп
A5: {='1 Полуфинал'!B6:B15} -> Coach | B5: =SUM(I5:J5) -> 5 | C5: =IF(COUNTIFS('Все игры'!AN$3:AN892,A5,'Все игры'!AS$3:AS892,"=1")=0, "", COUNTIFS('Все игры'!AN$3:AN892,A5,'Все игры'!AS$3:AS892,"=1")) | D5: =IF(COUNTIFS('Все игры'!AN$3:AN892,A5,'Все игры'!AS$3:AS892,"=0,50")=0, "", COUNTIFS('Все игры'!AN$3:AN892,A5,'Все игры'!AS$3:AS892,"=0,50")) | E5: =IF(COUNTIFS('Все игры'!AN$3:AN892,A5,'Все игры'!AR$3:AR892,"ПУ")=0, "", COUNTIFS('Все игры'!AN$3:AN892,A5,'Все игры'!AR$3:AR892,"ПУ")) | F5: =IFERROR(E5/I5,0) -> 0 | G5: =IF(COUNTIFS('Все игры'!AN$3:AN892,A5,'Все игры'!AR$3:AR892,"У/Победа")=0, "",COUNTIFS('Все игры'!AN$3:AN892,A5,'Все игры'!AR$3:AR892,"У/Победа") ) | H5: =IF(COUNTIFS('Все игры'!AN$3:AN892,A5,'Все игры'!AR$3:AR892,"У/Проигрыш")=0, "",COUNTIFS('Все игры'!AN$3:AN892,A5,'Все игры'!AR$3:AR892,"У/Проигрыш") ) | I5: =M5+N5+Q5+R5 -> 3 | J5: =K5+L5+O5+P5 -> 2 | K5: =COUNTIFS('Все игры'!AN$3:AN892,A5,'Все игры'!AP$3:AP892,">0",'Все игры'!AO$3:AO892,"Мафия") -> 0 | L5: =IFERROR(__xludf.dummyfunction("COUNTBLANK(FILTER('Все игры'!AN$3:AP892,'Все игры'!AN$3:AN892=A5,'Все игры'!AP$3:AP892 < 1,'Все игры'!AO$3:AO892=""Мафия""))"),2) -> 2 | M5: =COUNTIFS('Все игры'!AN$3:AN892,A5,'Все игры'!AP$3:AP892,">0",'Все игры'!AO$3:AO892,"Шериф") -> 0 | N5: =IFERROR(__xludf.dummyfunction("COUNTBLANK(FILTER('Все игры'!AN$3:AP892,'Все игры'!AN$3:AN892=A5,'Все игры'!AP$3:AP892 < 1,'Все игры'!AO$3:AO892=""Шериф""))"),1) -> 1 | O5: =COUNTIFS('Все игры'!AN$3:AN892,A5,'Все игры'!AP$3:AP892,">0",'Все игры'!AO$3:AO892,"Дон") -> 0 | P5: =IFERROR(__xludf.dummyfunction("COUNTBLANK(FILTER('Все игры'!AN$3:AP892,'Все игры'!AN$3:AN892=A5,'Все игры'!AP$3:AP892 < 1,'Все игры'!AO$3:AO892=""Дон""))"),0) -> 0 | Q5: =COUNTIFS('Все игры'!AN$3:AN892,A5,'Все игры'!AP$3:AP892,">0",'Все игры'!AO$3:AO892,"Мирный") -> 0 | R5: =IFERROR(__xludf.dummyfunction("COUNTBLANK(FILTER('Все игры'!AN$3:AP892,'Все игры'!AN$3:AN892=A5,'Все игры'!AP$3:AP892 < 1,'Все игры'!AO$3:AO892=""Мирный""))"),2) -> 2 | S5: =IFERROR((K5+M5+O5+Q5)/(I5+J5), ) -> 0 | T5: =IFERROR((M5+Q5)/I5, ) -> 0 | U5: =IFERROR((K5+O5)/J5, ) -> 0 | V5: =IFERROR(K5/(K5+L5), ) -> 0 | W5: =IFERROR(M5/(M5+N5), ) -> 0 | X5: =IFERROR(O5/(O5+P5), ) -> 0 | Y5: =IFERROR(Q5/(Q5+R5), ) -> 0 | Z5: =SUMIFS('Все игры'!AQ$3:AQ892,'Все игры'!AN$3:AN892,A5) -> 0 | AA5: =SUMIFS('Все игры'!AQ$3:AQ892,'Все игры'!AN$3:AN892,A5,'Все игры'!AO$3:AO892,"Мафия") -> 0 | AB5: =SUMIFS('Все игры'!AQ$3:AQ892,'Все игры'!AN$3:AN892,A5,'Все игры'!AO$3:AO892,"Шериф") -> 0 | AC5: =SUMIFS('Все игры'!AQ$3:AQ892,'Все игры'!AN$3:AN892,A5,'Все игры'!AO$3:AO892,"Дон") -> 0 | AD5: =SUMIFS('Все игры'!AQ$3:AQ892,'Все игры'!AN$3:AN892,A5,'Все игры'!AO$3:AO892,"Мирный") -> 0 | AE5: =IFERROR(Z5/B5,0) -> 0 | AF5: =IFERROR(AA5/(K5+L5),0) -> 0 | AG5: =IFERROR(AB5/(M5+N5),0) -> 0 | AH5: =IFERROR(AC5/(O5+P5),0) -> 0 | AI5: =IFERROR(AD5/(Q5+R5),0) -> 0
A6: Зверюга | B6: =SUM(I6:J6) -> 3 | C6: =IF(COUNTIFS('Все игры'!AN$3:AN892,A6,'Все игры'!AS$3:AS892,"=1")=0, "", COUNTIFS('Все игры'!AN$3:AN892,A6,'Все игры'!AS$3:AS892,"=1")) | D6: =IF(COUNTIFS('Все игры'!AN$3:AN892,A6,'Все игры'!AS$3:AS892,"=0,50")=0, "", COUNTIFS('Все игры'!AN$3:AN892,A6,'Все игры'!AS$3:AS892,"=0,50")) | E6: =IF(COUNTIFS('Все игры'!AN$3:AN892,A6,'Все игры'!AR$3:AR892,"ПУ")=0, "", COUNTIFS('Все игры'!AN$3:AN892,A6,'Все игры'!AR$3:AR892,"ПУ")) | F6: =IFERROR(E6/I6,0) -> 0 | G6: =IF(COUNTIFS('Все игры'!AN$3:AN892,A6,'Все игры'!AR$3:AR892,"У/Победа")=0, "",COUNTIFS('Все игры'!AN$3:AN892,A6,'Все игры'!AR$3:AR892,"У/Победа") ) | H6: =IF(COUNTIFS('Все игры'!AN$3:AN892,A6,'Все игры'!AR$3:AR892,"У/Проигрыш")=0, "",COUNTIFS('Все игры'!AN$3:AN892,A6,'Все игры'!AR$3:AR892,"У/Проигрыш") ) | I6: =M6+N6+Q6+R6 -> 2 | J6: =K6+L6+O6+P6 -> 1 | K6: =COUNTIFS('Все игры'!AN$3:AN892,A6,'Все игры'!AP$3:AP892,">0",'Все игры'!AO$3:AO892,"Мафия") -> 0 | L6: =IFERROR(__xludf.dummyfunction("COUNTBLANK(FILTER('Все игры'!AN$3:AP892,'Все игры'!AN$3:AN892=A6,'Все игры'!AP$3:AP892 < 1,'Все игры'!AO$3:AO892=""Мафия""))"),1) -> 1 | M6: =COUNTIFS('Все игры'!AN$3:AN892,A6,'Все игры'!AP$3:AP892,">0",'Все игры'!AO$3:AO892,"Шериф") -> 0 | N6: =IFERROR(__xludf.dummyfunction("COUNTBLANK(FILTER('Все игры'!AN$3:AP892,'Все игры'!AN$3:AN892=A6,'Все игры'!AP$3:AP892 < 1,'Все игры'!AO$3:AO892=""Шериф""))"),0) -> 0 | O6: =COUNTIFS('Все игры'!AN$3:AN892,A6,'Все игры'!AP$3:AP892,">0",'Все игры'!AO$3:AO892,"Дон") -> 0 | P6: =IFERROR(__xludf.dummyfunction("COUNTBLANK(FILTER('Все игры'!AN$3:AP892,'Все игры'!AN$3:AN892=A6,'Все игры'!AP$3:AP892 < 1,'Все игры'!AO$3:AO892=""Дон""))"),0) -> 0 | Q6: =COUNTIFS('Все игры'!AN$3:AN892,A6,'Все игры'!AP$3:AP892,">0",'Все игры'!AO$3:AO892,"Мирный") -> 0 | R6: =IFERROR(__xludf.dummyfunction("COUNTBLANK(FILTER('Все игры'!AN$3:AP892,'Все игры'!AN$3:AN892=A6,'Все игры'!AP$3:AP892 < 1,'Все игры'!AO$3:AO892=""Мирный""))"),2) -> 2 | S6: =IFERROR((K6+M6+O6+Q6)/(I6+J6), ) -> 0 | T6: =IFERROR((M6+Q6)/I6, ) -> 0 | U6: =IFERROR((K6+O6)/J6, ) -> 0 | V6: =IFERROR(K6/(K6+L6), ) -> 0 | W6: =IFERROR(M6/(M6+N6), ) -> 0 | X6: =IFERROR(O6/(O6+P6), ) -> 0 | Y6: =IFERROR(Q6/(Q6+R6), ) -> 0 | Z6: =SUMIFS('Все игры'!AQ$3:AQ892,'Все игры'!AN$3:AN892,A6) -> 0 | AA6: =SUMIFS('Все игры'!AQ$3:AQ892,'Все игры'!AN$3:AN892,A6,'Все игры'!AO$3:AO892,"Мафия") -> 0 | AB6: =SUMIFS('Все игры'!AQ$3:AQ892,'Все игры'!AN$3:AN892,A6,'Все игры'!AO$3:AO892,"Шериф") -> 0 | AC6: =SUMIFS('Все игры'!AQ$3:AQ892,'Все игры'!AN$3:AN892,A6,'Все игры'!AO$3:AO892,"Дон") -> 0 | AD6: =SUMIFS('Все игры'!AQ$3:AQ892,'Все игры'!AN$3:AN892,A6,'Все игры'!AO$3:AO892,"Мирный") -> 0 | AE6: =IFERROR(Z6/B6,0) -> 0 | AF6: =IFERROR(AA6/(K6+L6),0) -> 0 | AG6: =IFERROR(AB6/(M6+N6),0) -> 0 | AH6: =IFERROR(AC6/(O6+P6),0) -> 0 | AI6: =IFERROR(AD6/(Q6+R6),0) -> 0
A7: Чешир | B7: =SUM(I7:J7) -> 2 | C7: =IF(COUNTIFS('Все игры'!AN$3:AN892,A7,'Все игры'!AS$3:AS892,"=1")=0, "", COUNTIFS('Все игры'!AN$3:AN892,A7,'Все игры'!AS$3:AS892,"=1")) | D7: =IF(COUNTIFS('Все игры'!AN$3:AN892,A7,'Все игры'!AS$3:AS892,"=0,50")=0, "", COUNTIFS('Все игры'!AN$3:AN892,A7,'Все игры'!AS$3:AS892,"=0,50")) | E7: =IF(COUNTIFS('Все игры'!AN$3:AN892,A7,'Все игры'!AR$3:AR892,"ПУ")=0, "", COUNTIFS('Все игры'!AN$3:AN892,A7,'Все игры'!AR$3:AR892,"ПУ")) | F7: =IFERROR(E7/I7,0) -> 0 | G7: =IF(COUNTIFS('Все игры'!AN$3:AN892,A7,'Все игры'!AR$3:AR892,"У/Победа")=0, "",COUNTIFS('Все игры'!AN$3:AN892,A7,'Все игры'!AR$3:AR892,"У/Победа") ) | H7: =IF(COUNTIFS('Все игры'!AN$3:AN892,A7,'Все игры'!AR$3:AR892,"У/Проигрыш")=0, "",COUNTIFS('Все игры'!AN$3:AN892,A7,'Все игры'!AR$3:AR892,"У/Проигрыш") ) | I7: =M7+N7+Q7+R7 -> 2 | J7: =K7+L7+O7+P7 -> 0 | K7: =COUNTIFS('Все игры'!AN$3:AN892,A7,'Все игры'!AP$3:AP892,">0",'Все игры'!AO$3:AO892,"Мафия") -> 0 | L7: =IFERROR(__xludf.dummyfunction("COUNTBLANK(FILTER('Все игры'!AN$3:AP892,'Все игры'!AN$3:AN892=A7,'Все игры'!AP$3:AP892 < 1,'Все игры'!AO$3:AO892=""Мафия""))"),0) -> 0 | M7: =COUNTIFS('Все игры'!AN$3:AN892,A7,'Все игры'!AP$3:AP892,">0",'Все игры'!AO$3:AO892,"Шериф") -> 0 | N7: =IFERROR(__xludf.dummyfunction("COUNTBLANK(FILTER('Все игры'!AN$3:AP892,'Все игры'!AN$3:AN892=A7,'Все игры'!AP$3:AP892 < 1,'Все игры'!AO$3:AO892=""Шериф""))"),1) -> 1 | O7: =COUNTIFS('Все игры'!AN$3:AN892,A7,'Все игры'!AP$3:AP892,">0",'Все игры'!AO$3:AO892,"Дон") -> 0 | P7: =IFERROR(__xludf.dummyfunction("COUNTBLANK(FILTER('Все игры'!AN$3:AP892,'Все игры'!AN$3:AN892=A7,'Все игры'!AP$3:AP892 < 1,'Все игры'!AO$3:AO892=""Дон""))"),0) -> 0 | Q7: =COUNTIFS('Все игры'!AN$3:AN892,A7,'Все игры'!AP$3:AP892,">0",'Все игры'!AO$3:AO892,"Мирный") -> 0 | R7: =IFERROR(__xludf.dummyfunction("COUNTBLANK(FILTER('Все игры'!AN$3:AP892,'Все игры'!AN$3:AN892=A7,'Все игры'!AP$3:AP892 < 1,'Все игры'!AO$3:AO892=""Мирный""))"),1) -> 1 | S7: =IFERROR((K7+M7+O7+Q7)/(I7+J7), ) -> 0 | T7: =IFERROR((M7+Q7)/I7, ) -> 0 | U7: =IFERROR((K7+O7)/J7, ) -> 0 | V7: =IFERROR(K7/(K7+L7), ) -> 0 | W7: =IFERROR(M7/(M7+N7), ) -> 0 | X7: =IFERROR(O7/(O7+P7), ) -> 0 | Y7: =IFERROR(Q7/(Q7+R7), ) -> 0 | Z7: =SUMIFS('Все игры'!AQ$3:AQ892,'Все игры'!AN$3:AN892,A7) -> 0 | AA7: =SUMIFS('Все игры'!AQ$3:AQ892,'Все игры'!AN$3:AN892,A7,'Все игры'!AO$3:AO892,"Мафия") -> 0 | AB7: =SUMIFS('Все игры'!AQ$3:AQ892,'Все игры'!AN$3:AN892,A7,'Все игры'!AO$3:AO892,"Шериф") -> 0 | AC7: =SUMIFS('Все игры'!AQ$3:AQ892,'Все игры'!AN$3:AN892,A7,'Все игры'!AO$3:AO892,"Дон") -> 0 | AD7: =SUMIFS('Все игры'!AQ$3:AQ892,'Все игры'!AN$3:AN892,A7,'Все игры'!AO$3:AO892,"Мирный") -> 0 | AE7: =IFERROR(Z7/B7,0) -> 0 | AF7: =IFERROR(AA7/(K7+L7),0) -> 0 | AG7: =IFERROR(AB7/(M7+N7),0) -> 0 | AH7: =IFERROR(AC7/(O7+P7),0) -> 0 | AI7: =IFERROR(AD7/(Q7+R7),0) -> 0
A8: NME | B8: =SUM(I8:J8) -> 4 | C8: =IF(COUNTIFS('Все игры'!AN$3:AN892,A8,'Все игры'!AS$3:AS892,"=1")=0, "", COUNTIFS('Все игры'!AN$3:AN892,A8,'Все игры'!AS$3:AS892,"=1")) | D8: =IF(COUNTIFS('Все игры'!AN$3:AN892,A8,'Все игры'!AS$3:AS892,"=0,50")=0, "", COUNTIFS('Все игры'!AN$3:AN892,A8,'Все игры'!AS$3:AS892,"=0,50")) | E8: =IF(COUNTIFS('Все игры'!AN$3:AN892,A8,'Все игры'!AR$3:AR892,"ПУ")=0, "", COUNTIFS('Все игры'!AN$3:AN892,A8,'Все игры'!AR$3:AR892,"ПУ")) | F8: =IFERROR(E8/I8,0) -> 0 | G8: =IF(COUNTIFS('Все игры'!AN$3:AN892,A8,'Все игры'!AR$3:AR892,"У/Победа")=0, "",COUNTIFS('Все игры'!AN$3:AN892,A8,'Все игры'!AR$3:AR892,"У/Победа") ) | H8: =IF(COUNTIFS('Все игры'!AN$3:AN892,A8,'Все игры'!AR$3:AR892,"У/Проигрыш")=0, "",COUNTIFS('Все игры'!AN$3:AN892,A8,'Все игры'!AR$3:AR892,"У/Проигрыш") ) | I8: =M8+N8+Q8+R8 -> 2 | J8: =K8+L8+O8+P8 -> 2 | K8: =COUNTIFS('Все игры'!AN$3:AN892,A8,'Все игры'!AP$3:AP892,">0",'Все игры'!AO$3:AO892,"Мафия") -> 0 | L8: =IFERROR(__xludf.dummyfunction("COUNTBLANK(FILTER('Все игры'!AN$3:AP892,'Все игры'!AN$3:AN892=A8,'Все игры'!AP$3:AP892 < 1,'Все игры'!AO$3:AO892=""Мафия""))"),2) -> 2 | M8: =COUNTIFS('Все игры'!AN$3:AN892,A8,'Все игры'!AP$3:AP892,">0",'Все игры'!AO$3:AO892,"Шериф") -> 0 | N8: =IFERROR(__xludf.dummyfunction("COUNTBLANK(FILTER('Все игры'!AN$3:AP892,'Все игры'!AN$3:AN892=A8,'Все игры'!AP$3:AP892 < 1,'Все игры'!AO$3:AO892=""Шериф""))"),0) -> 0 | O8: =COUNTIFS('Все игры'!AN$3:AN892,A8,'Все игры'!AP$3:AP892,">0",'Все игры'!AO$3:AO892,"Дон") -> 0 | P8: =IFERROR(__xludf.dummyfunction("COUNTBLANK(FILTER('Все игры'!AN$3:AP892,'Все игры'!AN$3:AN892=A8,'Все игры'!AP$3:AP892 < 1,'Все игры'!AO$3:AO892=""Дон""))"),0) -> 0 | Q8: =COUNTIFS('Все игры'!AN$3:AN892,A8,'Все игры'!AP$3:AP892,">0",'Все игры'!AO$3:AO892,"Мирный") -> 0 | R8: =IFERROR(__xludf.dummyfunction("COUNTBLANK(FILTER('Все игры'!AN$3:AP892,'Все игры'!AN$3:AN892=A8,'Все игры'!AP$3:AP892 < 1,'Все игры'!AO$3:AO892=""Мирный""))"),2) -> 2 | S8: =IFERROR((K8+M8+O8+Q8)/(I8+J8), ) -> 0 | T8: =IFERROR((M8+Q8)/I8, ) -> 0 | U8: =IFERROR((K8+O8)/J8, ) -> 0 | V8: =IFERROR(K8/(K8+L8), ) -> 0 | W8: =IFERROR(M8/(M8+N8), ) -> 0 | X8: =IFERROR(O8/(O8+P8), ) -> 0 | Y8: =IFERROR(Q8/(Q8+R8), ) -> 0 | Z8: =SUMIFS('Все игры'!AQ$3:AQ892,'Все игры'!AN$3:AN892,A8) -> 0 | AA8: =SUMIFS('Все игры'!AQ$3:AQ892,'Все игры'!AN$3:AN892,A8,'Все игры'!AO$3:AO892,"Мафия") -> 0 | AB8: =SUMIFS('Все игры'!AQ$3:AQ892,'Все игры'!AN$3:AN892,A8,'Все игры'!AO$3:AO892,"Шериф") -> 0 | AC8: =SUMIFS('Все игры'!AQ$3:AQ892,'Все игры'!AN$3:AN892,A8,'Все игры'!AO$3:AO892,"Дон") -> 0 | AD8: =SUMIFS('Все игры'!AQ$3:AQ892,'Все игры'!AN$3:AN892,A8,'Все игры'!AO$3:AO892,"Мирный") -> 0 | AE8: =IFERROR(Z8/B8,0) -> 0 | AF8: =IFERROR(AA8/(K8+L8),0) -> 0 | AG8: =IFERROR(AB8/(M8+N8),0) -> 0 | AH8: =IFERROR(AC8/(O8+P8),0) -> 0 | AI8: =IFERROR(AD8/(Q8+R8),0) -> 0
A9: Still Rise | B9: =SUM(I9:J9) -> 4 | C9: =IF(COUNTIFS('Все игры'!AN$3:AN892,A9,'Все игры'!AS$3:AS892,"=1")=0, "", COUNTIFS('Все игры'!AN$3:AN892,A9,'Все игры'!AS$3:AS892,"=1")) | D9: =IF(COUNTIFS('Все игры'!AN$3:AN892,A9,'Все игры'!AS$3:AS892,"=0,50")=0, "", COUNTIFS('Все игры'!AN$3:AN892,A9,'Все игры'!AS$3:AS892,"=0,50")) | E9: =IF(COUNTIFS('Все игры'!AN$3:AN892,A9,'Все игры'!AR$3:AR892,"ПУ")=0, "", COUNTIFS('Все игры'!AN$3:AN892,A9,'Все игры'!AR$3:AR892,"ПУ")) | F9: =IFERROR(E9/I9,0) -> 0 | G9: =IF(COUNTIFS('Все игры'!AN$3:AN892,A9,'Все игры'!AR$3:AR892,"У/Победа")=0, "",COUNTIFS('Все игры'!AN$3:AN892,A9,'Все игры'!AR$3:AR892,"У/Победа") ) | H9: =IF(COUNTIFS('Все игры'!AN$3:AN892,A9,'Все игры'!AR$3:AR892,"У/Проигрыш")=0, "",COUNTIFS('Все игры'!AN$3:AN892,A9,'Все игры'!AR$3:AR892,"У/Проигрыш") ) | I9: =M9+N9+Q9+R9 -> 1 | J9: =K9+L9+O9+P9 -> 3 | K9: =COUNTIFS('Все игры'!AN$3:AN892,A9,'Все игры'!AP$3:AP892,">0",'Все игры'!AO$3:AO892,"Мафия") -> 0 | L9: =IFERROR(__xludf.dummyfunction("COUNTBLANK(FILTER('Все игры'!AN$3:AP892,'Все игры'!AN$3:AN892=A9,'Все игры'!AP$3:AP892 < 1,'Все игры'!AO$3:AO892=""Мафия""))"),0) -> 0 | M9: =COUNTIFS('Все игры'!AN$3:AN892,A9,'Все игры'!AP$3:AP892,">0",'Все игры'!AO$3:AO892,"Шериф") -> 0 | N9: =IFERROR(__xludf.dummyfunction("COUNTBLANK(FILTER('Все игры'!AN$3:AP892,'Все игры'!AN$3:AN892=A9,'Все игры'!AP$3:AP892 < 1,'Все игры'!AO$3:AO892=""Шериф""))"),0) -> 0 | O9: =COUNTIFS('Все игры'!AN$3:AN892,A9,'Все игры'!AP$3:AP892,">0",'Все игры'!AO$3:AO892,"Дон") -> 0 | P9: =IFERROR(__xludf.dummyfunction("COUNTBLANK(FILTER('Все игры'!AN$3:AP892,'Все игры'!AN$3:AN892=A9,'Все игры'!AP$3:AP892 < 1,'Все игры'!AO$3:AO892=""Дон""))"),3) -> 3 | Q9: =COUNTIFS('Все игры'!AN$3:AN892,A9,'Все игры'!AP$3:AP892,">0",'Все игры'!AO$3:AO892,"Мирный") -> 0 | R9: =IFERROR(__xludf.dummyfunction("COUNTBLANK(FILTER('Все игры'!AN$3:AP892,'Все игры'!AN$3:AN892=A9,'Все игры'!AP$3:AP892 < 1,'Все игры'!AO$3:AO892=""Мирный""))"),1) -> 1 | S9: =IFERROR((K9+M9+O9+Q9)/(I9+J9), ) -> 0 | T9: =IFERROR((M9+Q9)/I9, ) -> 0 | U9: =IFERROR((K9+O9)/J9, ) -> 0 | V9: =IFERROR(K9/(K9+L9), ) -> 0 | W9: =IFERROR(M9/(M9+N9), ) -> 0 | X9: =IFERROR(O9/(O9+P9), ) -> 0 | Y9: =IFERROR(Q9/(Q9+R9), ) -> 0 | Z9: =SUMIFS('Все игры'!AQ$3:AQ892,'Все игры'!AN$3:AN892,A9) -> 0 | AA9: =SUMIFS('Все игры'!AQ$3:AQ892,'Все игры'!AN$3:AN892,A9,'Все игры'!AO$3:AO892,"Мафия") -> 0 | AB9: =SUMIFS('Все игры'!AQ$3:AQ892,'Все игры'!AN$3:AN892,A9,'Все игры'!AO$3:AO892,"Шериф") -> 0 | AC9: =SUMIFS('Все игры'!AQ$3:AQ892,'Все игры'!AN$3:AN892,A9,'Все игры'!AO$3:AO892,"Дон") -> 0 | AD9: =SUMIFS('Все игры'!AQ$3:AQ892,'Все игры'!AN$3:AN892,A9,'Все игры'!AO$3:AO892,"Мирный") -> 0 | AE9: =IFERROR(Z9/B9,0) -> 0 | AF9: =IFERROR(AA9/(K9+L9),0) -> 0 | AG9: =IFERROR(AB9/(M9+N9),0) -> 0 | AH9: =IFERROR(AC9/(O9+P9),0) -> 0 | AI9: =IFERROR(AD9/(Q9+R9),0) -> 0
A10: Махинатор | B10: =SUM(I10:J10) -> 3 | C10: =IF(COUNTIFS('Все игры'!AN$3:AN892,A10,'Все игры'!AS$3:AS892,"=1")=0, "", COUNTIFS('Все игры'!AN$3:AN892,A10,'Все игры'!AS$3:AS892,"=1")) | D10: =IF(COUNTIFS('Все игры'!AN$3:AN892,A10,'Все игры'!AS$3:AS892,"=0,50")=0, "", COUNTIFS('Все игры'!AN$3:AN892,A10,'Все игры'!AS$3:AS892,"=0,50")) | E10: =IF(COUNTIFS('Все игры'!AN$3:AN892,A10,'Все игры'!AR$3:AR892,"ПУ")=0, "", COUNTIFS('Все игры'!AN$3:AN892,A10,'Все игры'!AR$3:AR892,"ПУ")) | F10: =IFERROR(E10/I10,0) -> 0 | G10: =IF(COUNTIFS('Все игры'!AN$3:AN892,A10,'Все игры'!AR$3:AR892,"У/Победа")=0, "",COUNTIFS('Все игры'!AN$3:AN892,A10,'Все игры'!AR$3:AR892,"У/Победа") ) | H10: =IF(COUNTIFS('Все игры'!AN$3:AN892,A10,'Все игры'!AR$3:AR892,"У/Проигрыш")=0, "",COUNTIFS('Все игры'!AN$3:AN892,A10,'Все игры'!AR$3:AR892,"У/Проигрыш") ) | I10: =M10+N10+Q10+R10 -> 3 | J10: =K10+L10+O10+P10 -> 0 | K10: =COUNTIFS('Все игры'!AN$3:AN892,A10,'Все игры'!AP$3:AP892,">0",'Все игры'!AO$3:AO892,"Мафия") -> 0 | L10: =IFERROR(__xludf.dummyfunction("COUNTBLANK(FILTER('Все игры'!AN$3:AP892,'Все игры'!AN$3:AN892=A10,'Все игры'!AP$3:AP892 < 1,'Все игры'!AO$3:AO892=""Мафия""))"),0) -> 0 | M10: =COUNTIFS('Все игры'!AN$3:AN892,A10,'Все игры'!AP$3:AP892,">0",'Все игры'!AO$3:AO892,"Шериф") -> 0 | N10: =IFERROR(__xludf.dummyfunction("COUNTBLANK(FILTER('Все игры'!AN$3:AP892,'Все игры'!AN$3:AN892=A10,'Все игры'!AP$3:AP892 < 1,'Все игры'!AO$3:AO892=""Шериф""))"),0) -> 0 | O10: =COUNTIFS('Все игры'!AN$3:AN892,A10,'Все игры'!AP$3:AP892,">0",'Все игры'!AO$3:AO892,"Дон") -> 0 | P10: =IFERROR(__xludf.dummyfunction("COUNTBLANK(FILTER('Все игры'!AN$3:AP892,'Все игры'!AN$3:AN892=A10,'Все игры'!AP$3:AP892 < 1,'Все игры'!AO$3:AO892=""Дон""))"),0) -> 0 | Q10: =COUNTIFS('Все игры'!AN$3:AN892,A10,'Все игры'!AP$3:AP892,">0",'Все игры'!AO$3:AO892,"Мирный") -> 0 | R10: =IFERROR(__xludf.dummyfunction("COUNTBLANK(FILTER('Все игры'!AN$3:AP892,'Все игры'!AN$3:AN892=A10,'Все игры'!AP$3:AP892 < 1,'Все игры'!AO$3:AO892=""Мирный""))"),3) -> 3 | S10: =IFERROR((K10+M10+O10+Q10)/(I10+J10), ) -> 0 | T10: =IFERROR((M10+Q10)/I10, ) -> 0 | U10: =IFERROR((K10+O10)/J10, ) -> 0 | V10: =IFERROR(K10/(K10+L10), ) -> 0 | W10: =IFERROR(M10/(M10+N10), ) -> 0 | X10: =IFERROR(O10/(O10+P10), ) -> 0 | Y10: =IFERROR(Q10/(Q10+R10), ) -> 0 | Z10: =SUMIFS('Все игры'!AQ$3:AQ892,'Все игры'!AN$3:AN892,A10) -> 0 | AA10: =SUMIFS('Все игры'!AQ$3:AQ892,'Все игры'!AN$3:AN892,A10,'Все игры'!AO$3:AO892,"Мафия") -> 0 | AB10: =SUMIFS('Все игры'!AQ$3:AQ892,'Все игры'!AN$3:AN892,A10,'Все игры'!AO$3:AO892,"Шериф") -> 0 | AC10: =SUMIFS('Все игры'!AQ$3:AQ892,'Все игры'!AN$3:AN892,A10,'Все игры'!AO$3:AO892,"Дон") -> 0 | AD10: =SUMIFS('Все игры'!AQ$3:AQ892,'Все игры'!AN$3:AN892,A10,'Все игры'!AO$3:AO892,"Мирный") -> 0 | AE10: =IFERROR(Z10/B10,0) -> 0 | AF10: =IFERROR(AA10/(K10+L10),0) -> 0 | AG10: =IFERROR(AB10/(M10+N10),0) -> 0 | AH10: =IFERROR(AC10/(O10+P10),0) -> 0 | AI10: =IFERROR(AD10/(Q10+R10),0) -> 0
A11: Cristo | B11: =SUM(I11:J11) -> 5 | C11: =IF(COUNTIFS('Все игры'!AN$3:AN892,A11,'Все игры'!AS$3:AS892,"=1")=0, "", COUNTIFS('Все игры'!AN$3:AN892,A11,'Все игры'!AS$3:AS892,"=1")) | D11: =IF(COUNTIFS('Все игры'!AN$3:AN892,A11,'Все игры'!AS$3:AS892,"=0,50")=0, "", COUNTIFS('Все игры'!AN$3:AN892,A11,'Все игры'!AS$3:AS892,"=0,50")) | E11: =IF(COUNTIFS('Все игры'!AN$3:AN892,A11,'Все игры'!AR$3:AR892,"ПУ")=0, "", COUNTIFS('Все игры'!AN$3:AN892,A11,'Все игры'!AR$3:AR892,"ПУ")) | F11: =IFERROR(E11/I11,0) -> 0 | G11: =IF(COUNTIFS('Все игры'!AN$3:AN892,A11,'Все игры'!AR$3:AR892,"У/Победа")=0, "",COUNTIFS('Все игры'!AN$3:AN892,A11,'Все игры'!AR$3:AR892,"У/Победа") ) | H11: =IF(COUNTIFS('Все игры'!AN$3:AN892,A11,'Все игры'!AR$3:AR892,"У/Проигрыш")=0, "",COUNTIFS('Все игры'!AN$3:AN892,A11,'Все игры'!AR$3:AR892,"У/Проигрыш") ) | I11: =M11+N11+Q11+R11 -> 3 | J11: =K11+L11+O11+P11 -> 2 | K11: =COUNTIFS('Все игры'!AN$3:AN892,A11,'Все игры'!AP$3:AP892,">0",'Все игры'!AO$3:AO892,"Мафия") -> 0 | L11: =IFERROR(__xludf.dummyfunction("COUNTBLANK(FILTER('Все игры'!AN$3:AP892,'Все игры'!AN$3:AN892=A11,'Все игры'!AP$3:AP892 < 1,'Все игры'!AO$3:AO892=""Мафия""))"),1) -> 1 | M11: =COUNTIFS('Все игры'!AN$3:AN892,A11,'Все игры'!AP$3:AP892,">0",'Все игры'!AO$3:AO892,"Шериф") -> 0 | N11: =IFERROR(__xludf.dummyfunction("COUNTBLANK(FILTER('Все игры'!AN$3:AP892,'Все игры'!AN$3:AN892=A11,'Все игры'!AP$3:AP892 < 1,'Все игры'!AO$3:AO892=""Шериф""))"),0) -> 0 | O11: =COUNTIFS('Все игры'!AN$3:AN892,A11,'Все игры'!AP$3:AP892,">0",'Все игры'!AO$3:AO892,"Дон") -> 0 | P11: =IFERROR(__xludf.dummyfunction("COUNTBLANK(FILTER('Все игры'!AN$3:AP892,'Все игры'!AN$3:AN892=A11,'Все игры'!AP$3:AP892 < 1,'Все игры'!AO$3:AO892=""Дон""))"),1) -> 1 | Q11: =COUNTIFS('Все игры'!AN$3:AN892,A11,'Все игры'!AP$3:AP892,">0",'Все игры'!AO$3:AO892,"Мирный") -> 0 | R11: =IFERROR(__xludf.dummyfunction("COUNTBLANK(FILTER('Все игры'!AN$3:AP892,'Все игры'!AN$3:AN892=A11,'Все игры'!AP$3:AP892 < 1,'Все игры'!AO$3:AO892=""Мирный""))"),3) -> 3 | S11: =IFERROR((K11+M11+O11+Q11)/(I11+J11), ) -> 0 | T11: =IFERROR((M11+Q11)/I11, ) -> 0 | U11: =IFERROR((K11+O11)/J11, ) -> 0 | V11: =IFERROR(K11/(K11+L11), ) -> 0 | W11: =IFERROR(M11/(M11+N11), ) -> 0 | X11: =IFERROR(O11/(O11+P11), ) -> 0 | Y11: =IFERROR(Q11/(Q11+R11), ) -> 0 | Z11: =SUMIFS('Все игры'!AQ$3:AQ892,'Все игры'!AN$3:AN892,A11) -> 0 | AA11: =SUMIFS('Все игры'!AQ$3:AQ892,'Все игры'!AN$3:AN892,A11,'Все игры'!AO$3:AO892,"Мафия") -> 0 | AB11: =SUMIFS('Все игры'!AQ$3:AQ892,'Все игры'!AN$3:AN892,A11,'Все игры'!AO$3:AO892,"Шериф") -> 0 | AC11: =SUMIFS('Все игры'!AQ$3:AQ892,'Все игры'!AN$3:AN892,A11,'Все игры'!AO$3:AO892,"Дон") -> 0 | AD11: =SUMIFS('Все игры'!AQ$3:AQ892,'Все игры'!AN$3:AN892,A11,'Все игры'!AO$3:AO892,"Мирный") -> 0 | AE11: =IFERROR(Z11/B11,0) -> 0 | AF11: =IFERROR(AA11/(K11+L11),0) -> 0 | AG11: =IFERROR(AB11/(M11+N11),0) -> 0 | AH11: =IFERROR(AC11/(O11+P11),0) -> 0 | AI11: =IFERROR(AD11/(Q11+R11),0) -> 0
A12: Арс | B12: =SUM(I12:J12) -> 4 | C12: =IF(COUNTIFS('Все игры'!AN$3:AN892,A12,'Все игры'!AS$3:AS892,"=1")=0, "", COUNTIFS('Все игры'!AN$3:AN892,A12,'Все игры'!AS$3:AS892,"=1")) | D12: =IF(COUNTIFS('Все игры'!AN$3:AN892,A12,'Все игры'!AS$3:AS892,"=0,50")=0, "", COUNTIFS('Все игры'!AN$3:AN892,A12,'Все игры'!AS$3:AS892,"=0,50")) | E12: =IF(COUNTIFS('Все игры'!AN$3:AN892,A12,'Все игры'!AR$3:AR892,"ПУ")=0, "", COUNTIFS('Все игры'!AN$3:AN892,A12,'Все игры'!AR$3:AR892,"ПУ")) | F12: =IFERROR(E12/I12,0) -> 0 | G12: =IF(COUNTIFS('Все игры'!AN$3:AN892,A12,'Все игры'!AR$3:AR892,"У/Победа")=0, "",COUNTIFS('Все игры'!AN$3:AN892,A12,'Все игры'!AR$3:AR892,"У/Победа") ) | H12: =IF(COUNTIFS('Все игры'!AN$3:AN892,A12,'Все игры'!AR$3:AR892,"У/Проигрыш")=0, "",COUNTIFS('Все игры'!AN$3:AN892,A12,'Все игры'!AR$3:AR892,"У/Проигрыш") ) | I12: =M12+N12+Q12+R12 -> 1 | J12: =K12+L12+O12+P12 -> 3 | K12: =COUNTIFS('Все игры'!AN$3:AN892,A12,'Все игры'!AP$3:AP892,">0",'Все игры'!AO$3:AO892,"Мафия") -> 0 | L12: =IFERROR(__xludf.dummyfunction("COUNTBLANK(FILTER('Все игры'!AN$3:AP892,'Все игры'!AN$3:AN892=A12,'Все игры'!AP$3:AP892 < 1,'Все игры'!AO$3:AO892=""Мафия""))"),2) -> 2 | M12: =COUNTIFS('Все игры'!AN$3:AN892,A12,'Все игры'!AP$3:AP892,">0",'Все игры'!AO$3:AO892,"Шериф") -> 0 | N12: =IFERROR(__xludf.dummyfunction("COUNTBLANK(FILTER('Все игры'!AN$3:AP892,'Все игры'!AN$3:AN892=A12,'Все игры'!AP$3:AP892 < 1,'Все игры'!AO$3:AO892=""Шериф""))"),0) -> 0 | O12: =COUNTIFS('Все игры'!AN$3:AN892,A12,'Все игры'!AP$3:AP892,">0",'Все игры'!AO$3:AO892,"Дон") -> 0 | P12: =IFERROR(__xludf.dummyfunction("COUNTBLANK(FILTER('Все игры'!AN$3:AP892,'Все игры'!AN$3:AN892=A12,'Все игры'!AP$3:AP892 < 1,'Все игры'!AO$3:AO892=""Дон""))"),1) -> 1 | Q12: =COUNTIFS('Все игры'!AN$3:AN892,A12,'Все игры'!AP$3:AP892,">0",'Все игры'!AO$3:AO892,"Мирный") -> 0 | R12: =IFERROR(__xludf.dummyfunction("COUNTBLANK(FILTER('Все игры'!AN$3:AP892,'Все игры'!AN$3:AN892=A12,'Все игры'!AP$3:AP892 < 1,'Все игры'!AO$3:AO892=""Мирный""))"),1) -> 1 | S12: =IFERROR((K12+M12+O12+Q12)/(I12+J12), ) -> 0 | T12: =IFERROR((M12+Q12)/I12, ) -> 0 | U12: =IFERROR((K12+O12)/J12, ) -> 0 | V12: =IFERROR(K12/(K12+L12), ) -> 0 | W12: =IFERROR(M12/(M12+N12), ) -> 0 | X12: =IFERROR(O12/(O12+P12), ) -> 0 | Y12: =IFERROR(Q12/(Q12+R12), ) -> 0 | Z12: =SUMIFS('Все игры'!AQ$3:AQ892,'Все игры'!AN$3:AN892,A12) -> 0 | AA12: =SUMIFS('Все игры'!AQ$3:AQ892,'Все игры'!AN$3:AN892,A12,'Все игры'!AO$3:AO892,"Мафия") -> 0 | AB12: =SUMIFS('Все игры'!AQ$3:AQ892,'Все игры'!AN$3:AN892,A12,'Все игры'!AO$3:AO892,"Шериф") -> 0 | AC12: =SUMIFS('Все игры'!AQ$3:AQ892,'Все игры'!AN$3:AN892,A12,'Все игры'!AO$3:AO892,"Дон") -> 0 | AD12: =SUMIFS('Все игры'!AQ$3:AQ892,'Все игры'!AN$3:AN892,A12,'Все игры'!AO$3:AO892,"Мирный") -> 0 | AE12: =IFERROR(Z12/B12,0) -> 0 | AF12: =IFERROR(AA12/(K12+L12),0) -> 0 | AG12: =IFERROR(AB12/(M12+N12),0) -> 0 | AH12: =IFERROR(AC12/(O12+P12),0) -> 0 | AI12: =IFERROR(AD12/(Q12+R12),0) -> 0
A13: Тихий Закат | B13: =SUM(I13:J13) -> 2 | C13: =IF(COUNTIFS('Все игры'!AN$3:AN892,A13,'Все игры'!AS$3:AS892,"=1")=0, "", COUNTIFS('Все игры'!AN$3:AN892,A13,'Все игры'!AS$3:AS892,"=1")) | D13: =IF(COUNTIFS('Все игры'!AN$3:AN892,A13,'Все игры'!AS$3:AS892,"=0,50")=0, "", COUNTIFS('Все игры'!AN$3:AN892,A13,'Все игры'!AS$3:AS892,"=0,50")) | E13: =IF(COUNTIFS('Все игры'!AN$3:AN892,A13,'Все игры'!AR$3:AR892,"ПУ")=0, "", COUNTIFS('Все игры'!AN$3:AN892,A13,'Все игры'!AR$3:AR892,"ПУ")) | F13: =IFERROR(E13/I13,0) -> 0 | G13: =IF(COUNTIFS('Все игры'!AN$3:AN892,A13,'Все игры'!AR$3:AR892,"У/Победа")=0, "",COUNTIFS('Все игры'!AN$3:AN892,A13,'Все игры'!AR$3:AR892,"У/Победа") ) | H13: =IF(COUNTIFS('Все игры'!AN$3:AN892,A13,'Все игры'!AR$3:AR892,"У/Проигрыш")=0, "",COUNTIFS('Все игры'!AN$3:AN892,A13,'Все игры'!AR$3:AR892,"У/Проигрыш") ) | I13: =M13+N13+Q13+R13 -> 2 | J13: =K13+L13+O13+P13 -> 0 | K13: =COUNTIFS('Все игры'!AN$3:AN892,A13,'Все игры'!AP$3:AP892,">0",'Все игры'!AO$3:AO892,"Мафия") -> 0 | L13: =IFERROR(__xludf.dummyfunction("COUNTBLANK(FILTER('Все игры'!AN$3:AP892,'Все игры'!AN$3:AN892=A13,'Все игры'!AP$3:AP892 < 1,'Все игры'!AO$3:AO892=""Мафия""))"),0) -> 0 | M13: =COUNTIFS('Все игры'!AN$3:AN892,A13,'Все игры'!AP$3:AP892,">0",'Все игры'!AO$3:AO892,"Шериф") -> 0 | N13: =IFERROR(__xludf.dummyfunction("COUNTBLANK(FILTER('Все игры'!AN$3:AP892,'Все игры'!AN$3:AN892=A13,'Все игры'!AP$3:AP892 < 1,'Все игры'!AO$3:AO892=""Шериф""))"),1) -> 1 | O13: =COUNTIFS('Все игры'!AN$3:AN892,A13,'Все игры'!AP$3:AP892,">0",'Все игры'!AO$3:AO892,"Дон") -> 0 | P13: =IFERROR(__xludf.dummyfunction("COUNTBLANK(FILTER('Все игры'!AN$3:AP892,'Все игры'!AN$3:AN892=A13,'Все игры'!AP$3:AP892 < 1,'Все игры'!AO$3:AO892=""Дон""))"),0) -> 0 | Q13: =COUNTIFS('Все игры'!AN$3:AN892,A13,'Все игры'!AP$3:AP892,">0",'Все игры'!AO$3:AO892,"Мирный") -> 0 | R13: =IFERROR(__xludf.dummyfunction("COUNTBLANK(FILTER('Все игры'!AN$3:AP892,'Все игры'!AN$3:AN892=A13,'Все игры'!AP$3:AP892 < 1,'Все игры'!AO$3:AO892=""Мирный""))"),1) -> 1 | S13: =IFERROR((K13+M13+O13+Q13)/(I13+J13), ) -> 0 | T13: =IFERROR((M13+Q13)/I13, ) -> 0 | U13: =IFERROR((K13+O13)/J13, ) -> 0 | V13: =IFERROR(K13/(K13+L13), ) -> 0 | W13: =IFERROR(M13/(M13+N13), ) -> 0 | X13: =IFERROR(O13/(O13+P13), ) -> 0 | Y13: =IFERROR(Q13/(Q13+R13), ) -> 0 | Z13: =SUMIFS('Все игры'!AQ$3:AQ892,'Все игры'!AN$3:AN892,A13) -> 0 | AA13: =SUMIFS('Все игры'!AQ$3:AQ892,'Все игры'!AN$3:AN892,A13,'Все игры'!AO$3:AO892,"Мафия") -> 0 | AB13: =SUMIFS('Все игры'!AQ$3:AQ892,'Все игры'!AN$3:AN892,A13,'Все игры'!AO$3:AO892,"Шериф") -> 0 | AC13: =SUMIFS('Все игры'!AQ$3:AQ892,'Все игры'!AN$3:AN892,A13,'Все игры'!AO$3:AO892,"Дон") -> 0 | AD13: =SUMIFS('Все игры'!AQ$3:AQ892,'Все игры'!AN$3:AN892,A13,'Все игры'!AO$3:AO892,"Мирный") -> 0 | AE13: =IFERROR(Z13/B13,0) -> 0 | AF13: =IFERROR(AA13/(K13+L13),0) -> 0 | AG13: =IFERROR(AB13/(M13+N13),0) -> 0 | AH13: =IFERROR(AC13/(O13+P13),0) -> 0 | AI13: =IFERROR(AD13/(Q13+R13),0) -> 0
A14: Cherry Pick | B14: =SUM(I14:J14) -> 4 | C14: =IF(COUNTIFS('Все игры'!AN$3:AN892,A14,'Все игры'!AS$3:AS892,"=1")=0, "", COUNTIFS('Все игры'!AN$3:AN892,A14,'Все игры'!AS$3:AS892,"=1")) | D14: =IF(COUNTIFS('Все игры'!AN$3:AN892,A14,'Все игры'!AS$3:AS892,"=0,50")=0, "", COUNTIFS('Все игры'!AN$3:AN892,A14,'Все игры'!AS$3:AS892,"=0,50")) | E14: =IF(COUNTIFS('Все игры'!AN$3:AN892,A14,'Все игры'!AR$3:AR892,"ПУ")=0, "", COUNTIFS('Все игры'!AN$3:AN892,A14,'Все игры'!AR$3:AR892,"ПУ")) | F14: =IFERROR(E14/I14,0) -> 0 | G14: =IF(COUNTIFS('Все игры'!AN$3:AN892,A14,'Все игры'!AR$3:AR892,"У/Победа")=0, "",COUNTIFS('Все игры'!AN$3:AN892,A14,'Все игры'!AR$3:AR892,"У/Победа") ) | H14: =IF(COUNTIFS('Все игры'!AN$3:AN892,A14,'Все игры'!AR$3:AR892,"У/Проигрыш")=0, "",COUNTIFS('Все игры'!AN$3:AN892,A14,'Все игры'!AR$3:AR892,"У/Проигрыш") ) | I14: =M14+N14+Q14+R14 -> 2 | J14: =K14+L14+O14+P14 -> 2 | K14: =COUNTIFS('Все игры'!AN$3:AN892,A14,'Все игры'!AP$3:AP892,">0",'Все игры'!AO$3:AO892,"Мафия") -> 0 | L14: =IFERROR(__xludf.dummyfunction("COUNTBLANK(FILTER('Все игры'!AN$3:AP892,'Все игры'!AN$3:AN892=A14,'Все игры'!AP$3:AP892 < 1,'Все игры'!AO$3:AO892=""Мафия""))"),2) -> 2 | M14: =COUNTIFS('Все игры'!AN$3:AN892,A14,'Все игры'!AP$3:AP892,">0",'Все игры'!AO$3:AO892,"Шериф") -> 0 | N14: =IFERROR(__xludf.dummyfunction("COUNTBLANK(FILTER('Все игры'!AN$3:AP892,'Все игры'!AN$3:AN892=A14,'Все игры'!AP$3:AP892 < 1,'Все игры'!AO$3:AO892=""Шериф""))"),0) -> 0 | O14: =COUNTIFS('Все игры'!AN$3:AN892,A14,'Все игры'!AP$3:AP892,">0",'Все игры'!AO$3:AO892,"Дон") -> 0 | P14: =IFERROR(__xludf.dummyfunction("COUNTBLANK(FILTER('Все игры'!AN$3:AP892,'Все игры'!AN$3:AN892=A14,'Все игры'!AP$3:AP892 < 1,'Все игры'!AO$3:AO892=""Дон""))"),0) -> 0 | Q14: =COUNTIFS('Все игры'!AN$3:AN892,A14,'Все игры'!AP$3:AP892,">0",'Все игры'!AO$3:AO892,"Мирный") -> 0 | R14: =IFERROR(__xludf.dummyfunction("COUNTBLANK(FILTER('Все игры'!AN$3:AP892,'Все игры'!AN$3:AN892=A14,'Все игры'!AP$3:AP892 < 1,'Все игры'!AO$3:AO892=""Мирный""))"),2) -> 2 | S14: =IFERROR((K14+M14+O14+Q14)/(I14+J14), ) -> 0 | T14: =IFERROR((M14+Q14)/I14, ) -> 0 | U14: =IFERROR((K14+O14)/J14, ) -> 0 | V14: =IFERROR(K14/(K14+L14), ) -> 0 | W14: =IFERROR(M14/(M14+N14), ) -> 0 | X14: =IFERROR(O14/(O14+P14), ) -> 0 | Y14: =IFERROR(Q14/(Q14+R14), ) -> 0 | Z14: =SUMIFS('Все игры'!AQ$3:AQ892,'Все игры'!AN$3:AN892,A14) -> 0 | AA14: =SUMIFS('Все игры'!AQ$3:AQ892,'Все игры'!AN$3:AN892,A14,'Все игры'!AO$3:AO892,"Мафия") -> 0 | AB14: =SUMIFS('Все игры'!AQ$3:AQ892,'Все игры'!AN$3:AN892,A14,'Все игры'!AO$3:AO892,"Шериф") -> 0 | AC14: =SUMIFS('Все игры'!AQ$3:AQ892,'Все игры'!AN$3:AN892,A14,'Все игры'!AO$3:AO892,"Дон") -> 0 | AD14: =SUMIFS('Все игры'!AQ$3:AQ892,'Все игры'!AN$3:AN892,A14,'Все игры'!AO$3:AO892,"Мирный") -> 0 | AE14: =IFERROR(Z14/B14,0) -> 0 | AF14: =IFERROR(AA14/(K14+L14),0) -> 0 | AG14: =IFERROR(AB14/(M14+N14),0) -> 0 | AH14: =IFERROR(AC14/(O14+P14),0) -> 0 | AI14: =IFERROR(AD14/(Q14+R14),0) -> 0
A16: 2 ПОЛУФИНАЛ
A17: Игрок | B17: Кол-во игр | C17: ЛХ полный | D17: ЛХ двойка | E17: ПУ | F17: Killrate | G17: Победил в угадайке | H17: Проиграл в угадайке | I17: Все красные (М+Ш) игр | J17: Все черные (Д+М) игр | K17: Мафия Побед | L17: Мафия Проигрышей | M17: Шериф Побед | N17: Шериф Проигрышей | O17: Дон Побед | P17: Дон Проигрышей | Q17: Мирный Побед | R17: Мирный Проигрышей | S17: WINRATE общий | T17: Все красные (М+Ш) % побед | U17: Все черные (Д+М) % побед | V17: Мафия: % Побед | W17: Шериф: % Побед | X17: Дон: % Побед | Y17: Мирный: % Побед | Z17: Всего: допы | AA17: Мафия: допы | AB17: Шериф: допы | AC17: Дон: допы | AD17: Мирный: допы | AE17: Общий: ср.доп | AF17: Мафия: ср. доп | AG17: Шериф: ср.доп | AH17: Дон: ср.доп | AI17: Мирный: ср.доп
A18: {='2 Полуфинал'!B6:B15} -> Армен 24 | B18: =SUM(I18:J18) -> 4 | C18: =IF(COUNTIFS('Все игры'!AV$3:AV892,A18,'Все игры'!BA$3:BA892,"=1")=0, "", COUNTIFS('Все игры'!AV$3:AV892,A18,'Все игры'!BA$3:BA892,"=1")) | D18: =IF(COUNTIFS('Все игры'!AV$3:AV892,A18,'Все игры'!BA$3:BA892,"=0,50")=0, "", COUNTIFS('Все игры'!AV$3:AV892,A18,'Все игры'!BA$3:BA892,"=0,50")) | E18: =IF(COUNTIFS('Все игры'!AV$3:AV892,A18,'Все игры'!AZ$3:AZ892,"ПУ")=0, "", COUNTIFS('Все игры'!AV$3:AV892,A18,'Все игры'!AZ$3:AZ892,"ПУ")) | F18: =IFERROR(E18/I18,0) -> 0 | G18: =IF(COUNTIFS('Все игры'!AV$3:AV892,A18,'Все игры'!AZ$3:AZ892,"У/Победа")=0, "",COUNTIFS('Все игры'!AV$3:AV892,A18,'Все игры'!AZ$3:AZ892,"У/Победа") ) | H18: =IF(COUNTIFS('Все игры'!AV$3:AV892,A18,'Все игры'!AZ$3:AZ892,"У/Проигрыш")=0, "",COUNTIFS('Все игры'!AV$3:AV892,A18,'Все игры'!AZ$3:AZ892,"У/Проигрыш") ) | I18: =M18+N18+Q18+R18 -> 3 | J18: =K18+L18+O18+P18 -> 1 | K18: =COUNTIFS('Все игры'!AV$3:AV892,A18,'Все игры'!AX$3:AX892,">0",'Все игры'!AW$3:AW892,"Мафия") -> 0 | L18: =IFERROR(__xludf.dummyfunction("COUNTBLANK(FILTER('Все игры'!AV$3:AX892,'Все игры'!AV$3:AV892=A18,'Все игры'!AX$3:AX892 < 1,'Все игры'!AW$3:AW892=""Мафия""))"),0) -> 0 | M18: =COUNTIFS('Все игры'!AV$3:AV892,A18,'Все игры'!AX$3:AX892,">0",'Все игры'!AW$3:AW892,"Шериф") -> 0 | N18: =IFERROR(__xludf.dummyfunction("COUNTBLANK(FILTER('Все игры'!AV$3:AX892,'Все игры'!AV$3:AV892=A18,'Все игры'!AX$3:AX892 < 1,'Все игры'!AW$3:AW892=""Шериф""))"),0) -> 0 | O18: =COUNTIFS('Все игры'!AV$3:AV892,A18,'Все игры'!AX$3:AX892,">0",'Все игры'!AW$3:AW892,"Дон") -> 0 | P18: =IFERROR(__xludf.dummyfunction("COUNTBLANK(FILTER('Все игры'!AV$3:AX892,'Все игры'!AV$3:AV892=A18,'Все игры'!AX$3:AX892 < 1,'Все игры'!AW$3:AW892=""Дон""))"),1) -> 1 | Q18: =COUNTIFS('Все игры'!AV$3:AV892,A18,'Все игры'!AX$3:AX892,">0",'Все игры'!AW$3:AW892,"Мирный") -> 0 | R18: =IFERROR(__xludf.dummyfunction("COUNTBLANK(FILTER('Все игры'!AV$3:AX892,'Все игры'!AV$3:AV892=A18,'Все игры'!AX$3:AX892 < 1,'Все игры'!AW$3:AW892=""Мирный""))"),3) -> 3 | S18: =IFERROR((K18+M18+O18+Q18)/(I18+J18), ) -> 0 | T18: =IFERROR((M18+Q18)/I18, ) -> 0 | U18: =IFERROR((K18+O18)/J18, ) -> 0 | V18: =IFERROR(K18/(K18+L18), ) -> 0 | W18: =IFERROR(M18/(M18+N18), ) -> 0 | X18: =IFERROR(O18/(O18+P18), ) -> 0 | Y18: =IFERROR(Q18/(Q18+R18), ) -> 0 | Z18: =SUMIFS('Все игры'!AY$3:AY892,'Все игры'!AV$3:AV892,A18) -> 0 | AA18: =SUMIFS('Все игры'!AY$3:AY892,'Все игры'!AV$3:AV892,A18,'Все игры'!AW$3:AW892,"Мафия") -> 0 | AB18: =SUMIFS('Все игры'!AY$3:AY892,'Все игры'!AV$3:AV892,A18,'Все игры'!AW$3:AW892,"Шериф") -> 0 | AC18: =SUMIFS('Все игры'!AY$3:AY892,'Все игры'!AV$3:AV892,A18,'Все игры'!AW$3:AW892,"Дон") -> 0 | AD18: =SUMIFS('Все игры'!AY$3:AY892,'Все игры'!AV$3:AV892,A18,'Все игры'!AW$3:AW892,"Мирный") -> 0 | AE18: =IFERROR(Z18/B18,0) -> 0 | AF18: =IFERROR(AA18/(K18+L18),0) -> 0 | AG18: =IFERROR(AB18/(M18+N18),0) -> 0 | AH18: =IFERROR(AC18/(O18+P18),0) -> 0 | AI18: =IFERROR(AD18/(Q18+R18),0) -> 0
A19: Наполеон | B19: =SUM(I19:J19) -> 4 | C19: =IF(COUNTIFS('Все игры'!AV$3:AV892,A19,'Все игры'!BA$3:BA892,"=1")=0, "", COUNTIFS('Все игры'!AV$3:AV892,A19,'Все игры'!BA$3:BA892,"=1")) | D19: =IF(COUNTIFS('Все игры'!AV$3:AV892,A19,'Все игры'!BA$3:BA892,"=0,50")=0, "", COUNTIFS('Все игры'!AV$3:AV892,A19,'Все игры'!BA$3:BA892,"=0,50")) | E19: =IF(COUNTIFS('Все игры'!AV$3:AV892,A19,'Все игры'!AZ$3:AZ892,"ПУ")=0, "", COUNTIFS('Все игры'!AV$3:AV892,A19,'Все игры'!AZ$3:AZ892,"ПУ")) | F19: =IFERROR(E19/I19,0) -> 0 | G19: =IF(COUNTIFS('Все игры'!AV$3:AV892,A19,'Все игры'!AZ$3:AZ892,"У/Победа")=0, "",COUNTIFS('Все игры'!AV$3:AV892,A19,'Все игры'!AZ$3:AZ892,"У/Победа") ) | H19: =IF(COUNTIFS('Все игры'!AV$3:AV892,A19,'Все игры'!AZ$3:AZ892,"У/Проигрыш")=0, "",COUNTIFS('Все игры'!AV$3:AV892,A19,'Все игры'!AZ$3:AZ892,"У/Проигрыш") ) | I19: =M19+N19+Q19+R19 -> 2 | J19: =K19+L19+O19+P19 -> 2 | K19: =COUNTIFS('Все игры'!AV$3:AV892,A19,'Все игры'!AX$3:AX892,">0",'Все игры'!AW$3:AW892,"Мафия") -> 0 | L19: =IFERROR(__xludf.dummyfunction("COUNTBLANK(FILTER('Все игры'!AV$3:AX892,'Все игры'!AV$3:AV892=A19,'Все игры'!AX$3:AX892 < 1,'Все игры'!AW$3:AW892=""Мафия""))"),2) -> 2 | M19: =COUNTIFS('Все игры'!AV$3:AV892,A19,'Все игры'!AX$3:AX892,">0",'Все игры'!AW$3:AW892,"Шериф") -> 0 | N19: =IFERROR(__xludf.dummyfunction("COUNTBLANK(FILTER('Все игры'!AV$3:AX892,'Все игры'!AV$3:AV892=A19,'Все игры'!AX$3:AX892 < 1,'Все игры'!AW$3:AW892=""Шериф""))"),1) -> 1 | O19: =COUNTIFS('Все игры'!AV$3:AV892,A19,'Все игры'!AX$3:AX892,">0",'Все игры'!AW$3:AW892,"Дон") -> 0 | P19: =IFERROR(__xludf.dummyfunction("COUNTBLANK(FILTER('Все игры'!AV$3:AX892,'Все игры'!AV$3:AV892=A19,'Все игры'!AX$3:AX892 < 1,'Все игры'!AW$3:AW892=""Дон""))"),0) -> 0 | Q19: =COUNTIFS('Все игры'!AV$3:AV892,A19,'Все игры'!AX$3:AX892,">0",'Все игры'!AW$3:AW892,"Мирный") -> 0 | R19: =IFERROR(__xludf.dummyfunction("COUNTBLANK(FILTER('Все игры'!AV$3:AX892,'Все игры'!AV$3:AV892=A19,'Все игры'!AX$3:AX892 < 1,'Все игры'!AW$3:AW892=""Мирный""))"),1) -> 1 | S19: =IFERROR((K19+M19+O19+Q19)/(I19+J19), ) -> 0 | T19: =IFERROR((M19+Q19)/I19, ) -> 0 | U19: =IFERROR((K19+O19)/J19, ) -> 0 | V19: =IFERROR(K19/(K19+L19), ) -> 0 | W19: =IFERROR(M19/(M19+N19), ) -> 0 | X19: =IFERROR(O19/(O19+P19), ) -> 0 | Y19: =IFERROR(Q19/(Q19+R19), ) -> 0 | Z19: =SUMIFS('Все игры'!AY$3:AY892,'Все игры'!AV$3:AV892,A19) -> 0 | AA19: =SUMIFS('Все игры'!AY$3:AY892,'Все игры'!AV$3:AV892,A19,'Все игры'!AW$3:AW892,"Мафия") -> 0 | AB19: =SUMIFS('Все игры'!AY$3:AY892,'Все игры'!AV$3:AV892,A19,'Все игры'!AW$3:AW892,"Шериф") -> 0 | AC19: =SUMIFS('Все игры'!AY$3:AY892,'Все игры'!AV$3:AV892,A19,'Все игры'!AW$3:AW892,"Дон") -> 0 | AD19: =SUMIFS('Все игры'!AY$3:AY892,'Все игры'!AV$3:AV892,A19,'Все игры'!AW$3:AW892,"Мирный") -> 0 | AE19: =IFERROR(Z19/B19,0) -> 0 | AF19: =IFERROR(AA19/(K19+L19),0) -> 0 | AG19: =IFERROR(AB19/(M19+N19),0) -> 0 | AH19: =IFERROR(AC19/(O19+P19),0) -> 0 | AI19: =IFERROR(AD19/(Q19+R19),0) -> 0
