Workbook

Sheet Турнирная таблица по Алфавиту
D1: Турнирная таблица Лиги "7+3"
B6: Место | C6: Игрок | D6: Количество игр | E6: Итоговый балл | F6: Средний балл за серию | G6: Средний доп балл (баллы от ведущих+ЛХ+Ci) | H6: Баллы за победу | I6: Баллы от ведущих | J6: ЛХ | K6: Ci | L6: ПУ | M6: Количество побед | N6: Победы за активные роли (Ш+Д) | O6: Проигрыши за активные роли (Ш+Д) | P6: ППК | Q6: Желтая карточка | R6: Штрафы по сумме всех карточек | S6: Штрафы дисциплинарные, опоздания, др. | T6: 1 серия | U6: 2 серия | V6: 3 серия | W6: 4 серия | X6: 5 серия | Y6: 6 серия | Z6: 7 серия | AA6: 8 серия | AB6: 9 серия | AC6: 10 серия | AD6: 11 серия | AE6: 12 серия | AF6: 13 серия | AG6: 14 серия | AH6: 15 серия | AI6: 16 серия | AJ6: 17 серия | AK6: 18 серия | AL6: 19 серия | AM6: 20 серия | AN6: 21 серия | AO6: 22 серия | AP6: 23 серия | AQ6: 24 серия | AR6: 25 серия | AS6: 26 серия | AT6: 27 серия | AU6: 28 серия | AV6: 29 серия | AW6: 30 серия | AX6: 31 серия | AY6: 32 серия | AZ6: 33 серия | BA6: 34 серия | BB6: 35 серия | BC6: 36 серия | BD6: 37 серия | BE6: 38 серия | BF6: 39 серия | BG6: 40 серия | BH6: 41 серия | BI6: 42 серия | BJ6: 43 серия | BK6: 44 серия | BL6: 45 серия | BM6: 46 серия | BN6: 47 серия | BO6: 48 серия | BP6: 49 серия | BQ6: 50 серия | BR6: 51 серия | BS6: 52 серия | BT6: 53 серия | BU6: 54 серия | BV6: 55 серия | BW6: 56 серия | BX6: 57 серия | BY6: 58 серия | BZ6: 59 серия | CA6: 60 серия
B7: =ROW()-6 -> 1 | C7: Авраам | D7: ='Игроки статистика'!B5 -> 50 | E7: =SUM(T7:CAZ7)-R7-S7 -> 191.5 | F7: =IFERROR((((E7)/D7)*5), ) -> 19.15 | G7: =IFERROR(((I7+J7+K7)/D7), ) -> 2.63 | H7: =SUMIFS('Все игры'!C$3:C1011,'Все игры'!A$3:A1011,C7) -> 60 | I7: =E7-H7-J7-K7 -> 128.5 | J7: =SUMIFS('Все игры'!F$3:F1011,'Все игры'!A$3:A1011,C7) -> 1 | K7: =SUMIFS('Все игры'!G$3:G1011,'Все игры'!A$3:A1011,C7) -> 2 | L7: ='Игроки статистика'!G5 -> 4 | M7: =H7/2.5 -> 24 | N7: =SUM('Игроки статистика'!O5,'Игроки статистика'!Q5) -> 5 | O7: =SUM('Игроки статистика'!P5,'Игроки статистика'!R5) -> 4 | P7: =IFERROR(__xludf.DUMMYFUNCTION("IFNA(SUM(FILTER('Штрафы'!$D$5:$D1011,'Штрафы'!$C$5:$C1011=C7)), )"),"") | Q7: =IFERROR(__xludf.DUMMYFUNCTION("IFNA(SUM(FILTER('Штрафы'!$F$5:$F1011,'Штрафы'!$C$5:$C1011=C7)), )"),"") | T7: =IFERROR(__xludf.DUMMYFUNCTION("IFNA(SUM(FILTER('1 серия'!$B$6:$C$15,'1 серия'!$B$6:$B$15=C7)), )"),"") | U7: =IFERROR(__xludf.DUMMYFUNCTION("IFNA(SUM(FILTER('2 серия'!$B$6:$C$15,'2 серия'!$B$6:$B$15=C7)), ) "),"") | V7: =IFERROR(__xludf.DUMMYFUNCTION("IFNA(SUM(FILTER('3 серия'!$B$6:$C$15,'3 серия'!$B$6:$B$15=C7)), ) "),"") | W7: =IFERROR(__xludf.DUMMYFUNCTION("IFNA(SUM(FILTER('4 серия'!$B$6:$C$15,'4 серия'!$B$6:$B$15=C7)), )"),22.75) -> 22.75 | X7: =IFERROR(__xludf.DUMMYFUNCTION("IFNA(SUM(FILTER('5 серия'!$B$6:$C$15,'5 серия'!$B$6:$B$15=C7)), )"),"") | Y7: =IFERROR(__xludf.DUMMYFUNCTION("IFNA(SUM(FILTER('6 серия'!$B$6:$C$15,'6 серия'!$B$6:$B$15=C7)), )"),"") | Z7: =IFERROR(__xludf.DUMMYFUNCTION("IFNA(SUM(FILTER('7 серия'!$B$6:$C$15,'7 серия'!$B$6:$B$15=C7)), )"),"") | AA7: =IFERROR(__xludf.DUMMYFUNCTION("IFNA(SUM(FILTER('8 серия'!$B$6:$C$15,'8 серия'!$B$6:$B$15=C7)), )"),"") | AB7: =IFERROR(__xludf.DUMMYFUNCTION("IFNA(SUM(FILTER('9 серия'!$B$7:$C$16,'9 серия'!$B$7:$B$16=C7)), )"),27.0) -> 27 | AC7: =IFERROR(__xludf.DUMMYFUNCTION("IFNA(SUM(FILTER('10 серия'!$B$6:$C$15,'10 серия'!$B$6:$B$15=C7)), )"),"") | AD7: =IFERROR(__xludf.DUMMYFUNCTION("IFNA(SUM(FILTER('11 серия'!$B$6:$C$15,'11 серия'!$B$6:$B$15=C7)), )"),"") | AE7: =IFERROR(__xludf.DUMMYFUNCTION("IFNA(SUM(FILTER('12 серия'!$B$6:$C$15,'12 серия'!$B$6:$B$15=C7)), )"),"") | AF7: =IFERROR(__xludf.DUMMYFUNCTION("IFNA(SUM(FILTER('13 серия'!$B$6:$C$15,'13 серия'!$B$6:$B$15=C7)), )"),"") | AG7: =IFERROR(__xludf.DUMMYFUNCTION("IFNA(SUM(FILTER('14 серия'!$B$6:$C$15,'14 серия'!$B$6:$B$15=C7)), )"),"") | AH7: =IFERROR(__xludf.DUMMYFUNCTION("IFNA(SUM(FILTER('15 серия'!$B$6:$C$15,'15 серия'!$B$6:$B$15=C7)), )"),"") | AI7: =IFERROR(__xludf.DUMMYFUNCTION("IFNA(SUM(FILTER('16 серия'!$B$6:$C$15,'16 серия'!$B$6:$B$15=C7)), )"),20.75) -> 20.75 | AJ7: =IFERROR(__xludf.DUMMYFUNCTION("IFNA(SUM(FILTER('17 серия'!$B$6:$C$15,'17 серия'!$B$6:$B$15=C7)), )"),"") | AK7: =IFERROR(__xludf.DUMMYFUNCTION("IFNA(SUM(FILTER('18 серия'!$B$6:$C$15,'18 серия'!$B$6:$B$15=C7)), )"),"") | AL7: =IFERROR(__xludf.DUMMYFUNCTION("IFNA(SUM(FILTER('19 серия'!$B$6:$C$15,'19 серия'!$B$6:$B$15=C7)), )"),"") | AM7: =IFERROR(__xludf.DUMMYFUNCTION("IFNA(SUM(FILTER('20 серия'!$B$6:$C$15,'20 серия'!$B$6:$B$15=C7)), )"),"") | AN7: =IFERROR(__xludf.DUMMYFUNCTION("IFNA(SUM(FILTER('21 серия'!$B$6:$C$15,'21 серия'!$B$6:$B$15=C7)), )"),"") | AO7: =IFERROR(__xludf.DUMMYFUNCTION("IFNA(SUM(FILTER('22 серия'!$B$6:$C$15,'22 серия'!$B$6:$B$15=C7)), )"),"") | AP7: =IFERROR(__xludf.DUMMYFUNCTION("IFNA(SUM(FILTER('23 серия'!$B$6:$C$15,'23 серия'!$B$6:$B$15=C7)), )"),"") | AQ7: =IFERROR(__xludf.DUMMYFUNCTION("IFNA(SUM(FILTER('24 серия'!$B$6:$C$15,'24 серия'!$B$6:$B$15=C7)), )"),"") | AR7: =IFERROR(__xludf.DUMMYFUNCTION("IFNA(SUM(FILTER('25 серия'!$B$6:$C$15,'25 серия'!$B$6:$B$15=C7)), )"),"") | AS7: =IFERROR(__xludf.DUMMYFUNCTION("IFNA(SUM(FILTER('26 серия'!$B$6:$C$15,'26 серия'!$B$6:$B$15=C7)), )"),15.75) -> 15.75 | AT7: =IFERROR(__xludf.DUMMYFUNCTION("IFNA(SUM(FILTER('27 серия'!$B$6:$C$15,'27 серия'!$B$6:$B$15=C7)), )"),"") | AU7: =IFERROR(__xludf.DUMMYFUNCTION("IFNA(SUM(FILTER('28 серия'!$B$6:$C$15,'28 серия'!$B$6:$B$15=C7)), )"),"") | AV7: =IFERROR(__xludf.DUMMYFUNCTION("IFNA(SUM(FILTER('29 серия'!$B$6:$C$15,'29 серия'!$B$6:$B$15=C7)), )"),"") | AW7: =IFERROR(__xludf.DUMMYFUNCTION("IFNA(SUM(FILTER('30 серия'!$B$6:$C$15,'30 серия'!$B$6:$B$15=C7)), )"),"") | AX7: =IFERROR(__xludf.DUMMYFUNCTION("IFNA(SUM(FILTER('31 серия'!$B$6:$C$15,'31 серия'!$B$6:$B$15=C7)), )"),18.25) -> 18.25 | AY7: =IFERROR(__xludf.DUMMYFUNCTION("IFNA(SUM(FILTER('32 серия'!$B$6:$C$15,'32 серия'!$B$6:$B$15=C7)), )"),"") | AZ7: =IFERROR(__xludf.DUMMYFUNCTION("IFNA(SUM(FILTER('33 серия'!$B$6:$C$15,'33 серия'!$B$6:$B$15=C7)), )"),"") | BA7: =IFERROR(__xludf.DUMMYFUNCTION("IFNA(SUM(FILTER('34 серия'!$B$6:$C$15,'34 серия'!$B$6:$B$15=C7)), )"),"") | BB7: =IFERROR(__xludf.DUMMYFUNCTION("IFNA(SUM(FILTER('35 серия'!$B$6:$C$15,'35 серия'!$B$6:$B$15=C7)), )"),"") | BC7: =IFERROR(__xludf.DUMMYFUNCTION("IFNA(SUM(FILTER('36 серия'!$B$6:$C$15,'36 серия'!$B$6:$B$15=C7)), )"),16.75) -> 16.75 | BD7: =IFERROR(__xludf.DUMMYFUNCTION("IFNA(SUM(FILTER('37 серия'!$B$6:$C$15,'37 серия'!$B$6:$B$15=C7)), )"),"") | BE7: =IFERROR(__xludf.DUMMYFUNCTION("IFNA(SUM(FILTER('38 серия'!$B$6:$C$15,'38 серия'!$B$6:$B$15=C7)), )"),"") | BF7: =IFERROR(__xludf.DUMMYFUNCTION("IFNA(SUM(FILTER('39 серия'!$B$6:$C$15,'39 серия'!$B$6:$B$15=C7)), )"),"") | BG7: =IFERROR(__xludf.DUMMYFUNCTION("IFNA(SUM(FILTER('40 серия'!$B$6:$C$15,'40 серия'!$B$6:$B$15=C7)), )"),20.5) -> 20.5 | BH7: =IFERROR(__xludf.DUMMYFUNCTION("IFNA(SUM(FILTER('41 серия'!$B$6:$C$15,'41 серия'!$B$6:$B$15=C7)), )"),"") | BI7: =IFERROR(__xludf.DUMMYFUNCTION("IFNA(SUM(FILTER('42 серия'!$B$6:$C$15,'42 серия'!$B$6:$B$15=C7)), )"),"") | BJ7: =IFERROR(__xludf.DUMMYFUNCTION("IFNA(SUM(FILTER('43 серия'!$B$6:$C$15,'43 серия'!$B$6:$B$15=C7)), )"),"") | BK7: =IFERROR(__xludf.DUMMYFUNCTION("IFNA(SUM(FILTER('44 серия'!$B$6:$C$15,'44 серия'!$B$6:$B$15=C7)), )"),17.5) -> 17.5 | BL7: =IFERROR(__xludf.DUMMYFUNCTION("IFNA(SUM(FILTER('45 серия'!$B$6:$C$15,'45 серия'!$B$6:$B$15=C7)), )"),"") | BM7: =IFERROR(__xludf.DUMMYFUNCTION("IFNA(SUM(FILTER('46 серия'!$B$6:$C$15,'46 серия'!$B$6:$B$15=C7)), )"),"") | BN7: =IFERROR(__xludf.DUMMYFUNCTION("IFNA(SUM(FILTER('47 серия'!$B$6:$C$15,'47 серия'!$B$6:$B$15=C7)), )"),"") | BO7: =IFERROR(__xludf.DUMMYFUNCTION("IFNA(SUM(FILTER('48 серия'!$B$6:$C$15,'48 серия'!$B$6:$B$15=$C7)), )"),"") | BP7: =IFERROR(__xludf.DUMMYFUNCTION("IFNA(SUM(FILTER('49 серия'!$B$6:$C$15,'49 серия'!$B$6:$B$15=$C7)), )"),"") | BQ7: =IFERROR(__xludf.DUMMYFUNCTION("IFNA(SUM(FILTER('50 серия'!$B$6:$C$15,'50 серия'!$B$6:$B$15=$C7)), )"),"") | BR7: =IFERROR(__xludf.DUMMYFUNCTION("IFNA(SUM(FILTER('51 серия'!$B$6:$C$15,'51 серия'!$B$6:$B$15=$C7)), )"),16.5) -> 16.5 | BS7: =IFERROR(__xludf.DUMMYFUNCTION("IFNA(SUM(FILTER('52 серия'!$B$6:$C$15,'52 серия'!$B$6:$B$15=C7)), )"),"") | BT7: =IFERROR(__xludf.DUMMYFUNCTION("IFNA(SUM(FILTER('53 серия'!$B$6:$C$15,'53 серия'!$B$6:$B$15=$C7)), )"),15.75) -> 15.75 | BU7: =IFERROR(__xludf.DUMMYFUNCTION("IFNA(SUM(FILTER('54 серия'!$B$6:$C$15,'54 серия'!$B$6:$B$15=$C7)), )"),"") | BV7: =IFERROR(__xludf.DUMMYFUNCTION("IFNA(SUM(FILTER('55 серия'!$B$6:$C$15,'55 серия'!$B$6:$B$15=$C7)), )"),"") | BW7: =IFERROR(__xludf.DUMMYFUNCTION("IFNA(SUM(FILTER('56 серия'!$B$6:$C$15,'56 серия'!$B$6:$B$15=$C7)), )"),"") | BX7: =IFERROR(__xludf.DUMMYFUNCTION("IFNA(SUM(FILTER('57 серия'!$B$6:$C$15,'57 серия'!$B$6:$B$15=$C7)), )"),"") | BY7: =IFERROR(__xludf.DUMMYFUNCTION("IFNA(SUM(FILTER('58 серия'!$B$6:$C$15,'58 серия'!$B$6:$B$15=$C7)), )"),"") | BZ7: =IFERROR(__xludf.DUMMYFUNCTION("IFNA(SUM(FILTER('59 серия'!$B$6:$C$15,'59 серия'!$B$6:$B$15=C7)), )"),"") | CA7: =IFERROR(__xludf.DUMMYFUNCTION("IFNA(SUM(FILTER('60 серия'!$B$6:$C$15,'60 серия'!$B$6:$B$15=$C7)), )"),"")
B8: =ROW()-6 -> 2 | C8: Админ | D8: ='Игроки статистика'!B6 -> 50 | E8: =SUM(T8:CAZ8)-R8-S8 -> 217.75 | F8: =IFERROR((((E8)/D8)*5), ) -> 21.775 | G8: =IFERROR(((I8+J8+K8)/D8), ) -> 3.005 | H8: =SUMIFS('Все игры'!C$3:C1011,'Все игры'!A$3:A1011,C8) -> 67.5 | I8: =E8-H8-J8-K8 -> 144.25 | J8: =SUMIFS('Все игры'!F$3:F1011,'Все игры'!A$3:A1011,C8) -> 2 | K8: =SUMIFS('Все игры'!G$3:G1011,'Все игры'!A$3:A1011,C8) -> 4 | L8: ='Игроки статистика'!G6 -> 7 | M8: =H8/2.5 -> 27 | N8: =SUM('Игроки статистика'!O6,'Игроки статистика'!Q6) -> 6 | O8: =SUM('Игроки статистика'!P6,'Игроки статистика'!R6) -> 6 | P8: =IFERROR(__xludf.DUMMYFUNCTION("IFNA(SUM(FILTER('Штрафы'!$D$5:$D1011,'Штрафы'!$C$5:$C1011=C8)), )"),"") | Q8: =IFERROR(__xludf.DUMMYFUNCTION("IFNA(SUM(FILTER('Штрафы'!$F$5:$F1011,'Штрафы'!$C$5:$C1011=C8)), )"),"") | T8: =IFERROR(__xludf.DUMMYFUNCTION("IFNA(SUM(FILTER('1 серия'!$B$6:$C$15,'1 серия'!$B$6:$B$15=C8)), )"),"") | U8: =IFERROR(__xludf.DUMMYFUNCTION("IFNA(SUM(FILTER('2 серия'!$B$6:$C$15,'2 серия'!$B$6:$B$15=C8)), ) "),"") | V8: =IFERROR(__xludf.DUMMYFUNCTION("IFNA(SUM(FILTER('3 серия'!$B$6:$C$15,'3 серия'!$B$6:$B$15=C8)), ) "),"") | W8: =IFERROR(__xludf.DUMMYFUNCTION("IFNA(SUM(FILTER('4 серия'!$B$6:$C$15,'4 серия'!$B$6:$B$15=C8)), )"),"") | X8: =IFERROR(__xludf.DUMMYFUNCTION("IFNA(SUM(FILTER('5 серия'!$B$6:$C$15,'5 серия'!$B$6:$B$15=C8)), )"),"") | Y8: =IFERROR(__xludf.DUMMYFUNCTION("IFNA(SUM(FILTER('6 серия'!$B$6:$C$15,'6 серия'!$B$6:$B$15=C8)), )"),"") | Z8: =IFERROR(__xludf.DUMMYFUNCTION("IFNA(SUM(FILTER('7 серия'!$B$6:$C$15,'7 серия'!$B$6:$B$15=C8)), )"),"") | AA8: =IFERROR(__xludf.DUMMYFUNCTION("IFNA(SUM(FILTER('8 серия'!$B$6:$C$15,'8 серия'!$B$6:$B$15=C8)), )"),"") | AB8: =IFERROR(__xludf.DUMMYFUNCTION("IFNA(SUM(FILTER('9 серия'!$B$7:$C$16,'9 серия'!$B$7:$B$16=C8)), )"),"") | AC8: =IFERROR(__xludf.DUMMYFUNCTION("IFNA(SUM(FILTER('10 серия'!$B$6:$C$15,'10 серия'!$B$6:$B$15=C8)), )"),"") | AD8: =IFERROR(__xludf.DUMMYFUNCTION("IFNA(SUM(FILTER('11 серия'!$B$6:$C$15,'11 серия'!$B$6:$B$15=C8)), )"),"") | AE8: =IFERROR(__xludf.DUMMYFUNCTION("IFNA(SUM(FILTER('12 серия'!$B$6:$C$15,'12 серия'!$B$6:$B$15=C8)), )"),"") | AF8: =IFERROR(__xludf.DUMMYFUNCTION("IFNA(SUM(FILTER('13 серия'!$B$6:$C$15,'13 серия'!$B$6:$B$15=C8)), )"),"") | AG8: =IFERROR(__xludf.DUMMYFUNCTION("IFNA(SUM(FILTER('14 серия'!$B$6:$C$15,'14 серия'!$B$6:$B$15=C8)), )"),"") | AH8: =IFERROR(__xludf.DUMMYFUNCTION("IFNA(SUM(FILTER('15 серия'!$B$6:$C$15,'15 серия'!$B$6:$B$15=C8)), )"),"") | AI8: =IFERROR(__xludf.DUMMYFUNCTION("IFNA(SUM(FILTER('16 серия'!$B$6:$C$15,'16 серия'!$B$6:$B$15=C8)), )"),"") | AJ8: =IFERROR(__xludf.DUMMYFUNCTION("IFNA(SUM(FILTER('17 серия'!$B$6:$C$15,'17 серия'!$B$6:$B$15=C8)), )"),"") | AK8: =IFERROR(__xludf.DUMMYFUNCTION("IFNA(SUM(FILTER('18 серия'!$B$6:$C$15,'18 серия'!$B$6:$B$15=C8)), )"),"") | AL8: =IFERROR(__xludf.DUMMYFUNCTION("IFNA(SUM(FILTER('19 серия'!$B$6:$C$15,'19 серия'!$B$6:$B$15=C8)), )"),"") | AM8: =IFERROR(__xludf.DUMMYFUNCTION("IFNA(SUM(FILTER('20 серия'!$B$6:$C$15,'20 серия'!$B$6:$B$15=C8)), )"),"") | AN8: =IFERROR(__xludf.DUMMYFUNCTION("IFNA(SUM(FILTER('21 серия'!$B$6:$C$15,'21 серия'!$B$6:$B$15=C8)), )"),"") | AO8: =IFERROR(__xludf.DUMMYFUNCTION("IFNA(SUM(FILTER('22 серия'!$B$6:$C$15,'22 серия'!$B$6:$B$15=C8)), )"),"") | AP8: =IFERROR(__xludf.DUMMYFUNCTION("IFNA(SUM(FILTER('23 серия'!$B$6:$C$15,'23 серия'!$B$6:$B$15=C8)), )"),"") | AQ8: =IFERROR(__xludf.DUMMYFUNCTION("IFNA(SUM(FILTER('24 серия'!$B$6:$C$15,'24 серия'!$B$6:$B$15=C8)), )"),"") | AR8: =IFERROR(__xludf.DUMMYFUNCTION("IFNA(SUM(FILTER('25 серия'!$B$6:$C$15,'25 серия'!$B$6:$B$15=C8)), )"),26.5) -> 26.5 | AS8: =IFERROR(__xludf.DUMMYFUNCTION("IFNA(SUM(FILTER('26 серия'!$B$6:$C$15,'26 серия'!$B$6:$B$15=C8)), )"),27.0) -> 27 | AT8: =IFERROR(__xludf.DUMMYFUNCTION("IFNA(SUM(FILTER('27 серия'!$B$6:$C$15,'27 серия'!$B$6:$B$15=C8)), )"),18.0) -> 18 | AU8: =IFERROR(__xludf.DUMMYFUNCTION("IFNA(SUM(FILTER('28 серия'!$B$6:$C$15,'28 серия'!$B$6:$B$15=C8)), )"),24.25) -> 24.25 | AV8: =IFERROR(__xludf.DUMMYFUNCTION("IFNA(SUM(FILTER('29 серия'!$B$6:$C$15,'29 серия'!$B$6:$B$15=C8)), )"),14.25) -> 14.25 | AW8: =IFERROR(__xludf.DUMMYFUNCTION("IFNA(SUM(FILTER('30 серия'!$B$6:$C$15,'30 серия'!$B$6:$B$15=C8)), )"),14.0) -> 14 | AX8: =IFERROR(__xludf.DUMMYFUNCTION("IFNA(SUM(FILTER('31 серия'!$B$6:$C$15,'31 серия'!$B$6:$B$15=C8)), )"),25.75) -> 25.75 | AY8: =IFERROR(__xludf.DUMMYFUNCTION("IFNA(SUM(FILTER('32 серия'!$B$6:$C$15,'32 серия'!$B$6:$B$15=C8)), )"),22.5) -> 22.5 | AZ8: =IFERROR(__xludf.DUMMYFUNCTION("IFNA(SUM(FILTER('33 серия'!$B$6:$C$15,'33 серия'!$B$6:$B$15=C8)), )"),21.5) -> 21.5 | BA8: =IFERROR(__xludf.DUMMYFUNCTION("IFNA(SUM(FILTER('34 серия'!$B$6:$C$15,'34 серия'!$B$6:$B$15=C8)), )"),24.0) -> 24 | BB8: =IFERROR(__xludf.DUMMYFUNCTION("IFNA(SUM(FILTER('35 серия'!$B$6:$C$15,'35 серия'!$B$6:$B$15=C8)), )"),"") | BC8: =IFERROR(__xludf.DUMMYFUNCTION("IFNA(SUM(FILTER('36 серия'!$B$6:$C$15,'36 серия'!$B$6:$B$15=C8)), )"),"") | BD8: =IFERROR(__xludf.DUMMYFUNCTION("IFNA(SUM(FILTER('37 серия'!$B$6:$C$15,'37 серия'!$B$6:$B$15=C8)), )"),"") | BE8: =IFERROR(__xludf.DUMMYFUNCTION("IFNA(SUM(FILTER('38 серия'!$B$6:$C$15,'38 серия'!$B$6:$B$15=C8)), )"),"") | BF8: =IFERROR(__xludf.DUMMYFUNCTION("IFNA(SUM(FILTER('39 серия'!$B$6:$C$15,'39 серия'!$B$6:$B$15=C8)), )"),"") | BG8: =IFERROR(__xludf.DUMMYFUNCTION("IFNA(SUM(FILTER('40 серия'!$B$6:$C$15,'40 серия'!$B$6:$B$15=C8)), )"),"") | BH8: =IFERROR(__xludf.DUMMYFUNCTION("IFNA(SUM(FILTER('41 серия'!$B$6:$C$15,'41 серия'!$B$6:$B$15=C8)), )"),"") | BI8: =IFERROR(__xludf.DUMMYFUNCTION("IFNA(SUM(FILTER('42 серия'!$B$6:$C$15,'42 серия'!$B$6:$B$15=C8)), )"),"") | BJ8: =IFERROR(__xludf.DUMMYFUNCTION("IFNA(SUM(FILTER('43 серия'!$B$6:$C$15,'43 серия'!$B$6:$B$15=C8)), )"),"") | BK8: =IFERROR(__xludf.DUMMYFUNCTION("IFNA(SUM(FILTER('44 серия'!$B$6:$C$15,'44 серия'!$B$6:$B$15=C8)), )"),"") | BL8: =IFERROR(__xludf.DUMMYFUNCTION("IFNA(SUM(FILTER('45 серия'!$B$6:$C$15,'45 серия'!$B$6:$B$15=C8)), )"),"") | BM8: =IFERROR(__xludf.DUMMYFUNCTION("IFNA(SUM(FILTER('46 серия'!$B$6:$C$15,'46 серия'!$B$6:$B$15=C8)), )"),"") | BN8: =IFERROR(__xludf.DUMMYFUNCTION("IFNA(SUM(FILTER('47 серия'!$B$6:$C$15,'47 серия'!$B$6:$B$15=C8)), )"),"") | BO8: =IFERROR(__xludf.DUMMYFUNCTION("IFNA(SUM(FILTER('48 серия'!$B$6:$C$15,'48 серия'!$B$6:$B$15=$C8)), )"),"") | BP8: =IFERROR(__xludf.DUMMYFUNCTION("IFNA(SUM(FILTER('49 серия'!$B$6:$C$15,'49 серия'!$B$6:$B$15=$C8)), )"),"") | BQ8: =IFERROR(__xludf.DUMMYFUNCTION("IFNA(SUM(FILTER('50 серия'!$B$6:$C$15,'50 серия'!$B$6:$B$15=$C8)), )"),"") | BR8: =IFERROR(__xludf.DUMMYFUNCTION("IFNA(SUM(FILTER('51 серия'!$B$6:$C$15,'51 серия'!$B$6:$B$15=$C8)), )"),"") | BS8: =IFERROR(__xludf.DUMMYFUNCTION("IFNA(SUM(FILTER('52 серия'!$B$6:$C$15,'52 серия'!$B$6:$B$15=C8)), )"),"") | BT8: =IFERROR(__xludf.DUMMYFUNCTION("IFNA(SUM(FILTER('53 серия'!$B$6:$C$15,'53 серия'!$B$6:$B$15=$C8)), )"),"") | BU8: =IFERROR(__xludf.DUMMYFUNCTION("IFNA(SUM(FILTER('54 серия'!$B$6:$C$15,'54 серия'!$B$6:$B$15=$C8)), )"),"") | BV8: =IFERROR(__xludf.DUMMYFUNCTION("IFNA(SUM(FILTER('55 серия'!$B$6:$C$15,'55 серия'!$B$6:$B$15=$C8)), )"),"") | BW8: =IFERROR(__xludf.DUMMYFUNCTION("IFNA(SUM(FILTER('56 серия'!$B$6:$C$15,'56 серия'!$B$6:$B$15=$C8)), )"),"") | BX8: =IFERROR(__xludf.DUMMYFUNCTION("IFNA(SUM(FILTER('57 серия'!$B$6:$C$15,'57 серия'!$B$6:$B$15=$C8)), )"),"") | BY8: =IFERROR(__xludf.DUMMYFUNCTION("IFNA(SUM(FILTER('58 серия'!$B$6:$C$15,'58 серия'!$B$6:$B$15=$C8)), )"),"") | BZ8: =IFERROR(__xludf.DUMMYFUNCTION("IFNA(SUM(FILTER('59 серия'!$B$6:$C$15,'59 серия'!$B$6:$B$15=C8)), )"),"") | CA8: =IFERROR(__xludf.DUMMYFUNCTION("IFNA(SUM(FILTER('60 серия'!$B$6:$C$15,'60 серия'!$B$6:$B$15=$C8)), )"),"")
B9: =ROW()-6 -> 3 | C9: Андерсен | D9: ='Игроки статистика'!B7 -> 50 | E9: =SUM(T9:CAZ9)-R9-S9 -> 196.5 | F9: =IFERROR((((E9)/D9)*5), ) -> 19.65 | G9: =IFERROR(((I9+J9+K9)/D9), ) -> 2.73 | H9: =SUMIFS('Все игры'!C$3:C1011,'Все игры'!A$3:A1011,C9) -> 60 | I9: =E9-H9-J9-K9 -> 132 | J9: =SUMIFS('Все игры'!F$3:F1011,'Все игры'!A$3:A1011,C9) -> 1.5 | K9: =SUMIFS('Все игры'!G$3:G1011,'Все игры'!A$3:A1011,C9) -> 3 | L9: ='Игроки статистика'!G7 -> 5 | M9: =H9/2.5 -> 24 | N9: =SUM('Игроки статистика'!O7,'Игроки статистика'!Q7) -> 4 | O9: =SUM('Игроки статистика'!P7,'Игроки статистика'!R7) -> 6 | P9: =IFERROR(__xludf.DUMMYFUNCTION("IFNA(SUM(FILTER('Штрафы'!$D$5:$D1011,'Штрафы'!$C$5:$C1011=C9)), )"),"") | Q9: =IFERROR(__xludf.DUMMYFUNCTION("IFNA(SUM(FILTER('Штрафы'!$F$5:$F1011,'Штрафы'!$C$5:$C1011=C9)), )"),"") | T9: =IFERROR(__xludf.DUMMYFUNCTION("IFNA(SUM(FILTER('1 серия'!$B$6:$C$15,'1 серия'!$B$6:$B$15=C9)), )"),"") | U9: =IFERROR(__xludf.DUMMYFUNCTION("IFNA(SUM(FILTER('2 серия'!$B$6:$C$15,'2 серия'!$B$6:$B$15=C9)), ) "),20.0) -> 20 | V9: =IFERROR(__xludf.DUMMYFUNCTION("IFNA(SUM(FILTER('3 серия'!$B$6:$C$15,'3 серия'!$B$6:$B$15=C9)), ) "),"") | W9: =IFERROR(__xludf.DUMMYFUNCTION("IFNA(SUM(FILTER('4 серия'!$B$6:$C$15,'4 серия'!$B$6:$B$15=C9)), )"),"") | X9: =IFERROR(__xludf.DUMMYFUNCTION("IFNA(SUM(FILTER('5 серия'!$B$6:$C$15,'5 серия'!$B$6:$B$15=C9)), )"),"") | Y9: =IFERROR(__xludf.DUMMYFUNCTION("IFNA(SUM(FILTER('6 серия'!$B$6:$C$15,'6 серия'!$B$6:$B$15=C9)), )"),"") | Z9: =IFERROR(__xludf.DUMMYFUNCTION("IFNA(SUM(FILTER('7 серия'!$B$6:$C$15,'7 серия'!$B$6:$B$15=C9)), )"),"") | AA9: =IFERROR(__xludf.DUMMYFUNCTION("IFNA(SUM(FILTER('8 серия'!$B$6:$C$15,'8 серия'!$B$6:$B$15=C9)), )"),"") | AB9: =IFERROR(__xludf.DUMMYFUNCTION("IFNA(SUM(FILTER('9 серия'!$B$7:$C$16,'9 серия'!$B$7:$B$16=C9)), )"),"") | AC9: =IFERROR(__xludf.DUMMYFUNCTION("IFNA(SUM(FILTER('10 серия'!$B$6:$C$15,'10 серия'!$B$6:$B$15=C9)), )"),22.0) -> 22 | AD9: =IFERROR(__xludf.DUMMYFUNCTION("IFNA(SUM(FILTER('11 серия'!$B$6:$C$15,'11 серия'!$B$6:$B$15=C9)), )"),25.0) -> 25 | AE9: =IFERROR(__xludf.DUMMYFUNCTION("IFNA(SUM(FILTER('12 серия'!$B$6:$C$15,'12 серия'!$B$6:$B$15=C9)), )"),"") | AF9: =IFERROR(__xludf.DUMMYFUNCTION("IFNA(SUM(FILTER('13 серия'!$B$6:$C$15,'13 серия'!$B$6:$B$15=C9)), )"),"") | AG9: =IFERROR(__xludf.DUMMYFUNCTION("IFNA(SUM(FILTER('14 серия'!$B$6:$C$15,'14 серия'!$B$6:$B$15=C9)), )"),"") | AH9: =IFERROR(__xludf.DUMMYFUNCTION("IFNA(SUM(FILTER('15 серия'!$B$6:$C$15,'15 серия'!$B$6:$B$15=C9)), )"),"") | AI9: =IFERROR(__xludf.DUMMYFUNCTION("IFNA(SUM(FILTER('16 серия'!$B$6:$C$15,'16 серия'!$B$6:$B$15=C9)), )"),"") | AJ9: =IFERROR(__xludf.DUMMYFUNCTION("IFNA(SUM(FILTER('17 серия'!$B$6:$C$15,'17 серия'!$B$6:$B$15=C9)), )"),20.5) -> 20.5 | AK9: =IFERROR(__xludf.DUMMYFUNCTION("IFNA(SUM(FILTER('18 серия'!$B$6:$C$15,'18 серия'!$B$6:$B$15=C9)), )"),"") | AL9: =IFERROR(__xludf.DUMMYFUNCTION("IFNA(SUM(FILTER('19 серия'!$B$6:$C$15,'19 серия'!$B$6:$B$15=C9)), )"),"") | AM9: =IFERROR(__xludf.DUMMYFUNCTION("IFNA(SUM(FILTER('20 серия'!$B$6:$C$15,'20 серия'!$B$6:$B$15=C9)), )"),"") | AN9: =IFERROR(__xludf.DUMMYFUNCTION("IFNA(SUM(FILTER('21 серия'!$B$6:$C$15,'21 серия'!$B$6:$B$15=C9)), )"),"") | AO9: =IFERROR(__xludf.DUMMYFUNCTION("IFNA(SUM(FILTER('22 серия'!$B$6:$C$15,'22 серия'!$B$6:$B$15=C9)), )"),"") | AP9: =IFERROR(__xludf.DUMMYFUNCTION("IFNA(SUM(FILTER('23 серия'!$B$6:$C$15,'23 серия'!$B$6:$B$15=C9)), )"),"") | AQ9: =IFERROR(__xludf.DUMMYFUNCTION("IFNA(SUM(FILTER('24 серия'!$B$6:$C$15,'24 серия'!$B$6:$B$15=C9)), )"),"") | AR9: =IFERROR(__xludf.DUMMYFUNCTION("IFNA(SUM(FILTER('25 серия'!$B$6:$C$15,'25 серия'!$B$6:$B$15=C9)), )"),16.0) -> 16 | AS9: =IFERROR(__xludf.DUMMYFUNCTION("IFNA(SUM(FILTER('26 серия'!$B$6:$C$15,'26 серия'!$B$6:$B$15=C9)), )"),"") | AT9: =IFERROR(__xludf.DUMMYFUNCTION("IFNA(SUM(FILTER('27 серия'!$B$6:$C$15,'27 серия'!$B$6:$B$15=C9)), )"),"") | AU9: =IFERROR(__xludf.DUMMYFUNCTION("IFNA(SUM(FILTER('28 серия'!$B$6:$C$15,'28 серия'!$B$6:$B$15=C9)), )"),"") | AV9: =IFERROR(__xludf.DUMMYFUNCTION("IFNA(SUM(FILTER('29 серия'!$B$6:$C$15,'29 серия'!$B$6:$B$15=C9)), )"),19.25) -> 19.25 | AW9: =IFERROR(__xludf.DUMMYFUNCTION("IFNA(SUM(FILTER('30 серия'!$B$6:$C$15,'30 серия'!$B$6:$B$15=C9)), )"),"") | AX9: =IFERROR(__xludf.DUMMYFUNCTION("IFNA(SUM(FILTER('31 серия'!$B$6:$C$15,'31 серия'!$B$6:$B$15=C9)), )"),"") | AY9: =IFERROR(__xludf.DUMMYFUNCTION("IFNA(SUM(FILTER('32 серия'!$B$6:$C$15,'32 серия'!$B$6:$B$15=C9)), )"),"") | AZ9: =IFERROR(__xludf.DUMMYFUNCTION("IFNA(SUM(FILTER('33 серия'!$B$6:$C$15,'33 серия'!$B$6:$B$15=C9)), )"),"") | BA9: =IFERROR(__xludf.DUMMYFUNCTION("IFNA(SUM(FILTER('34 серия'!$B$6:$C$15,'34 серия'!$B$6:$B$15=C9)), )"),"") | BB9: =IFERROR(__xludf.DUMMYFUNCTION("IFNA(SUM(FILTER('35 серия'!$B$6:$C$15,'35 серия'!$B$6:$B$15=C9)), )"),18.75) -> 18.75 | BC9: =IFERROR(__xludf.DUMMYFUNCTION("IFNA(SUM(FILTER('36 серия'!$B$6:$C$15,'36 серия'!$B$6:$B$15=C9)), )"),"") | BD9: =IFERROR(__xludf.DUMMYFUNCTION("IFNA(SUM(FILTER('37 серия'!$B$6:$C$15,'37 серия'!$B$6:$B$15=C9)), )"),"") | BE9: =IFERROR(__xludf.DUMMYFUNCTION("IFNA(SUM(FILTER('38 серия'!$B$6:$C$15,'38 серия'!$B$6:$B$15=C9)), )"),"") | BF9: =IFERROR(__xludf.DUMMYFUNCTION("IFNA(SUM(FILTER('39 серия'!$B$6:$C$15,'39 серия'!$B$6:$B$15=C9)), )"),"") | BG9: =IFERROR(__xludf.DUMMYFUNCTION("IFNA(SUM(FILTER('40 серия'!$B$6:$C$15,'40 серия'!$B$6:$B$15=C9)), )"),"") | BH9: =IFERROR(__xludf.DUMMYFUNCTION("IFNA(SUM(FILTER('41 серия'!$B$6:$C$15,'41 серия'!$B$6:$B$15=C9)), )"),"") | BI9: =IFERROR(__xludf.DUMMYFUNCTION("IFNA(SUM(FILTER('42 серия'!$B$6:$C$15,'42 серия'!$B$6:$B$15=C9)), )"),"") | BJ9: =IFERROR(__xludf.DUMMYFUNCTION("IFNA(SUM(FILTER('43 серия'!$B$6:$C$15,'43 серия'!$B$6:$B$15=C9)), )"),"") | BK9: =IFERROR(__xludf.DUMMYFUNCTION("IFNA(SUM(FILTER('44 серия'!$B$6:$C$15,'44 серия'!$B$6:$B$15=C9)), )"),"") | BL9: =IFERROR(__xludf.DUMMYFUNCTION("IFNA(SUM(FILTER('45 серия'!$B$6:$C$15,'45 серия'!$B$6:$B$15=C9)), )"),"") | BM9: =IFERROR(__xludf.DUMMYFUNCTION("IFNA(SUM(FILTER('46 серия'!$B$6:$C$15,'46 серия'!$B$6:$B$15=C9)), )"),21.25) -> 21.25 | BN9: =IFERROR(__xludf.DUMMYFUNCTION("IFNA(SUM(FILTER('47 серия'!$B$6:$C$15,'47 серия'!$B$6:$B$15=C9)), )"),"") | BO9: =IFERROR(__xludf.DUMMYFUNCTION("IFNA(SUM(FILTER('48 серия'!$B$6:$C$15,'48 серия'!$B$6:$B$15=$C9)), )"),13.25) -> 13.25 | BP9: =IFERROR(__xludf.DUMMYFUNCTION("IFNA(SUM(FILTER('49 серия'!$B$6:$C$15,'49 серия'!$B$6:$B$15=$C9)), )"),"") | BQ9: =IFERROR(__xludf.DUMMYFUNCTION("IFNA(SUM(FILTER('50 серия'!$B$6:$C$15,'50 серия'!$B$6:$B$15=$C9)), )"),"") | BR9: =IFERROR(__xludf.DUMMYFUNCTION("IFNA(SUM(FILTER('51 серия'!$B$6:$C$15,'51 серия'!$B$6:$B$15=$C9)), )"),"") | BS9: =IFERROR(__xludf.DUMMYFUNCTION("IFNA(SUM(FILTER('52 серия'!$B$6:$C$15,'52 серия'!$B$6:$B$15=C9)), )"),"") | BT9: =IFERROR(__xludf.DUMMYFUNCTION("IFNA(SUM(FILTER('53 серия'!$B$6:$C$15,'53 серия'!$B$6:$B$15=$C9)), )"),"") | BU9: =IFERROR(__xludf.DUMMYFUNCTION("IFNA(SUM(FILTER('54 серия'!$B$6:$C$15,'54 серия'!$B$6:$B$15=$C9)), )"),"") | BV9: =IFERROR(__xludf.DUMMYFUNCTION("IFNA(SUM(FILTER('55 серия'!$B$6:$C$15,'55 серия'!$B$6:$B$15=$C9)), )"),"") | BW9: =IFERROR(__xludf.DUMMYFUNCTION("IFNA(SUM(FILTER('56 серия'!$B$6:$C$15,'56 серия'!$B$6:$B$15=$C9)), )"),"") | BX9: =IFERROR(__xludf.DUMMYFUNCTION("IFNA(SUM(FILTER('57 серия'!$B$6:$C$15,'57 серия'!$B$6:$B$15=$C9)), )"),"") | BY9: =IFERROR(__xludf.DUMMYFUNCTION("IFNA(SUM(FILTER('58 серия'!$B$6:$C$15,'58 серия'!$B$6:$B$15=$C9)), )"),20.5) -> 20.5 | BZ9: =IFERROR(__xludf.DUMMYFUNCTION("IFNA(SUM(FILTER('59 серия'!$B$6:$C$15,'59 серия'!$B$6:$B$15=C9)), )"),"") | CA9: =IFERROR(__xludf.DUMMYFUNCTION("IFNA(SUM(FILTER('60 серия'!$B$6:$C$15,'60 серия'!$B$6:$B$15=$C9)), )"),"")
B10: =ROW()-6 -> 4 | C10: Артик | D10: ='Игроки статистика'!B8 -> 50 | E10: =SUM(T10:CAZ10)-R10-S10 -> 244.5 | F10: =IFERROR((((E10)/D10)*5), ) -> 24.45 | G10: =IFERROR(((I10+J10+K10)/D10), ) -> 3.29 | H10: =SUMIFS('Все игры'!C$3:C1011,'Все игры'!A$3:A1011,C10) -> 80 | I10: =E10-H10-J10-K10 -> 153.5 | J10: =SUMIFS('Все игры'!F$3:F1011,'Все игры'!A$3:A1011,C10) -> 1.5 | K10: =SUMIFS('Все игры'!G$3:G1011,'Все игры'!A$3:A1011,C10) -> 9.5 | L10: ='Игроки статистика'!G8 -> 14 | M10: =H10/2.5 -> 32 | N10: =SUM('Игроки статистика'!O8,'Игроки статистика'!Q8) -> 7 | O10: =SUM('Игроки статистика'!P8,'Игроки статистика'!R8) -> 4 | P10: =IFERROR(__xludf.DUMMYFUNCTION("IFNA(SUM(FILTER('Штрафы'!$D$5:$D1011,'Штрафы'!$C$5:$C1011=C10)), )"),"") | Q10: =IFERROR(__xludf.DUMMYFUNCTION("IFNA(SUM(FILTER('Штрафы'!$F$5:$F1011,'Штрафы'!$C$5:$C1011=C10)), )"),"") | T10: =IFERROR(__xludf.DUMMYFUNCTION("IFNA(SUM(FILTER('1 серия'!$B$6:$C$15,'1 серия'!$B$6:$B$15=C10)), )"),27.5) -> 27.5 | U10: =IFERROR(__xludf.DUMMYFUNCTION("IFNA(SUM(FILTER('2 серия'!$B$6:$C$15,'2 серия'!$B$6:$B$15=C10)), ) "),"") | V10: =IFERROR(__xludf.DUMMYFUNCTION("IFNA(SUM(FILTER('3 серия'!$B$6:$C$15,'3 серия'!$B$6:$B$15=C10)), ) "),"") | W10: =IFERROR(__xludf.DUMMYFUNCTION("IFNA(SUM(FILTER('4 серия'!$B$6:$C$15,'4 серия'!$B$6:$B$15=C10)), )"),"") | X10: =IFERROR(__xludf.DUMMYFUNCTION("IFNA(SUM(FILTER('5 серия'!$B$6:$C$15,'5 серия'!$B$6:$B$15=C10)), )"),"") | Y10: =IFERROR(__xludf.DUMMYFUNCTION("IFNA(SUM(FILTER('6 серия'!$B$6:$C$15,'6 серия'!$B$6:$B$15=C10)), )"),15.5) -> 15.5 | Z10: =IFERROR(__xludf.DUMMYFUNCTION("IFNA(SUM(FILTER('7 серия'!$B$6:$C$15,'7 серия'!$B$6:$B$15=C10)), )"),"") | AA10: =IFERROR(__xludf.DUMMYFUNCTION("IFNA(SUM(FILTER('8 серия'!$B$6:$C$15,'8 серия'!$B$6:$B$15=C10)), )"),"") | AB10: =IFERROR(__xludf.DUMMYFUNCTION("IFNA(SUM(FILTER('9 серия'!$B$7:$C$16,'9 серия'!$B$7:$B$16=C10)), )"),"") | AC10: =IFERROR(__xludf.DUMMYFUNCTION("IFNA(SUM(FILTER('10 серия'!$B$6:$C$15,'10 серия'!$B$6:$B$15=C10)), )"),"") | AD10: =IFERROR(__xludf.DUMMYFUNCTION("IFNA(SUM(FILTER('11 серия'!$B$6:$C$15,'11 серия'!$B$6:$B$15=C10)), )"),"") | AE10: =IFERROR(__xludf.DUMMYFUNCTION("IFNA(SUM(FILTER('12 серия'!$B$6:$C$15,'12 серия'!$B$6:$B$15=C10)), )"),"") | AF10: =IFERROR(__xludf.DUMMYFUNCTION("IFNA(SUM(FILTER('13 серия'!$B$6:$C$15,'13 серия'!$B$6:$B$15=C10)), )"),"") | AG10: =IFERROR(__xludf.DUMMYFUNCTION("IFNA(SUM(FILTER('14 серия'!$B$6:$C$15,'14 серия'!$B$6:$B$15=C10)), )"),29.25) -> 29.25 | AH10: =IFERROR(__xludf.DUMMYFUNCTION("IFNA(SUM(FILTER('15 серия'!$B$6:$C$15,'15 серия'!$B$6:$B$15=C10)), )"),28.0) -> 28 | AI10: =IFERROR(__xludf.DUMMYFUNCTION("IFNA(SUM(FILTER('16 серия'!$B$6:$C$15,'16 серия'!$B$6:$B$15=C10)), )"),"") | AJ10: =IFERROR(__xludf.DUMMYFUNCTION("IFNA(SUM(FILTER('17 серия'!$B$6:$C$15,'17 серия'!$B$6:$B$15=C10)), )"),"") | AK10: =IFERROR(__xludf.DUMMYFUNCTION("IFNA(SUM(FILTER('18 серия'!$B$6:$C$15,'18 серия'!$B$6:$B$15=C10)), )"),"") | AL10: =IFERROR(__xludf.DUMMYFUNCTION("IFNA(SUM(FILTER('19 серия'!$B$6:$C$15,'19 серия'!$B$6:$B$15=C10)), )"),"") | AM10: =IFERROR(__xludf.DUMMYFUNCTION("IFNA(SUM(FILTER('20 серия'!$B$6:$C$15,'20 серия'!$B$6:$B$15=C10)), )"),"") | AN10: =IFERROR(__xludf.DUMMYFUNCTION("IFNA(SUM(FILTER('21 серия'!$B$6:$C$15,'21 серия'!$B$6:$B$15=C10)), )"),"") | AO10: =IFERROR(__xludf.DUMMYFUNCTION("IFNA(SUM(FILTER('22 серия'!$B$6:$C$15,'22 серия'!$B$6:$B$15=C10)), )"),"") | AP10: =IFERROR(__xludf.DUMMYFUNCTION("IFNA(SUM(FILTER('23 серия'!$B$6:$C$15,'23 серия'!$B$6:$B$15=C10)), )"),"") | AQ10: =IFERROR(__xludf.DUMMYFUNCTION("IFNA(SUM(FILTER('24 серия'!$B$6:$C$15,'24 серия'!$B$6:$B$15=C10)), )"),"") | AR10: =IFERROR(__xludf.DUMMYFUNCTION("IFNA(SUM(FILTER('25 серия'!$B$6:$C$15,'25 серия'!$B$6:$B$15=C10)), )"),"") | AS10: =IFERROR(__xludf.DUMMYFUNCTION("IFNA(SUM(FILTER('26 серия'!$B$6:$C$15,'26 серия'!$B$6:$B$15=C10)), )"),"") | AT10: =IFERROR(__xludf.DUMMYFUNCTION("IFNA(SUM(FILTER('27 серия'!$B$6:$C$15,'27 серия'!$B$6:$B$15=C10)), )"),"") | AU10: =IFERROR(__xludf.DUMMYFUNCTION("IFNA(SUM(FILTER('28 серия'!$B$6:$C$15,'28 серия'!$B$6:$B$15=C10)), )"),"") | AV10: =IFERROR(__xludf.DUMMYFUNCTION("IFNA(SUM(FILTER('29 серия'!$B$6:$C$15,'29 серия'!$B$6:$B$15=C10)), )"),"") | AW10: =IFERROR(__xludf.DUMMYFUNCTION("IFNA(SUM(FILTER('30 серия'!$B$6:$C$15,'30 серия'!$B$6:$B$15=C10)), )"),"") | AX10: =IFERROR(__xludf.DUMMYFUNCTION("IFNA(SUM(FILTER('31 серия'!$B$6:$C$15,'31 серия'!$B$6:$B$15=C10)), )"),"") | AY10: =IFERROR(__xludf.DUMMYFUNCTION("IFNA(SUM(FILTER('32 серия'!$B$6:$C$15,'32 серия'!$B$6:$B$15=C10)), )"),"") | AZ10: =IFERROR(__xludf.DUMMYFUNCTION("IFNA(SUM(FILTER('33 серия'!$B$6:$C$15,'33 серия'!$B$6:$B$15=C10)), )"),"") | BA10: =IFERROR(__xludf.DUMMYFUNCTION("IFNA(SUM(FILTER('34 серия'!$B$6:$C$15,'34 серия'!$B$6:$B$15=C10)), )"),24.5) -> 24.5 | BB10: =IFERROR(__xludf.DUMMYFUNCTION("IFNA(SUM(FILTER('35 серия'!$B$6:$C$15,'35 серия'!$B$6:$B$15=C10)), )"),"") | BC10: =IFERROR(__xludf.DUMMYFUNCTION("IFNA(SUM(FILTER('36 серия'!$B$6:$C$15,'36 серия'!$B$6:$B$15=C10)), )"),22.25) -> 22.25 | BD10: =IFERROR(__xludf.DUMMYFUNCTION("IFNA(SUM(FILTER('37 серия'!$B$6:$C$15,'37 серия'!$B$6:$B$15=C10)), )"),"") | BE10: =IFERROR(__xludf.DUMMYFUNCTION("IFNA(SUM(FILTER('38 серия'!$B$6:$C$15,'38 серия'!$B$6:$B$15=C10)), )"),"") | BF10: =IFERROR(__xludf.DUMMYFUNCTION("IFNA(SUM(FILTER('39 серия'!$B$6:$C$15,'39 серия'!$B$6:$B$15=C10)), )"),"") | BG10: =IFERROR(__xludf.DUMMYFUNCTION("IFNA(SUM(FILTER('40 серия'!$B$6:$C$15,'40 серия'!$B$6:$B$15=C10)), )"),28.0) -> 28 | BH10: =IFERROR(__xludf.DUMMYFUNCTION("IFNA(SUM(FILTER('41 серия'!$B$6:$C$15,'41 серия'!$B$6:$B$15=C10)), )"),"") | BI10: =IFERROR(__xludf.DUMMYFUNCTION("IFNA(SUM(FILTER('42 серия'!$B$6:$C$15,'42 серия'!$B$6:$B$15=C10)), )"),"") | BJ10: =IFERROR(__xludf.DUMMYFUNCTION("IFNA(SUM(FILTER('43 серия'!$B$6:$C$15,'43 серия'!$B$6:$B$15=C10)), )"),"") | BK10: =IFERROR(__xludf.DUMMYFUNCTION("IFNA(SUM(FILTER('44 серия'!$B$6:$C$15,'44 серия'!$B$6:$B$15=C10)), )"),"") | BL10: =IFERROR(__xludf.DUMMYFUNCTION("IFNA(SUM(FILTER('45 серия'!$B$6:$C$15,'45 серия'!$B$6:$B$15=C10)), )"),"") | BM10: =IFERROR(__xludf.DUMMYFUNCTION("IFNA(SUM(FILTER('46 серия'!$B$6:$C$15,'46 серия'!$B$6:$B$15=C10)), )"),"") | BN10: =IFERROR(__xludf.DUMMYFUNCTION("IFNA(SUM(FILTER('47 серия'!$B$6:$C$15,'47 серия'!$B$6:$B$15=C10)), )"),"") | BO10: =IFERROR(__xludf.DUMMYFUNCTION("IFNA(SUM(FILTER('48 серия'!$B$6:$C$15,'48 серия'!$B$6:$B$15=$C10)), )"),"") | BP10: =IFERROR(__xludf.DUMMYFUNCTION("IFNA(SUM(FILTER('49 серия'!$B$6:$C$15,'49 серия'!$B$6:$B$15=$C10)), )"),16.0) -> 16 | BQ10: =IFERROR(__xludf.DUMMYFUNCTION("IFNA(SUM(FILTER('50 серия'!$B$6:$C$15,'50 серия'!$B$6:$B$15=$C10)), )"),"") | BR10: =IFERROR(__xludf.DUMMYFUNCTION("IFNA(SUM(FILTER('51 серия'!$B$6:$C$15,'51 серия'!$B$6:$B$15=$C10)), )"),"") | BS10: =IFERROR(__xludf.DUMMYFUNCTION("IFNA(SUM(FILTER('52 серия'!$B$6:$C$15,'52 серия'!$B$6:$B$15=C10)), )"),"") | BT10: =IFERROR(__xludf.DUMMYFUNCTION("IFNA(SUM(FILTER('53 серия'!$B$6:$C$15,'53 серия'!$B$6:$B$15=$C10)), )"),"") | BU10: =IFERROR(__xludf.DUMMYFUNCTION("IFNA(SUM(FILTER('54 серия'!$B$6:$C$15,'54 серия'!$B$6:$B$15=$C10)), )"),27.0) -> 27 | BV10: =IFERROR(__xludf.DUMMYFUNCTION("IFNA(SUM(FILTER('55 серия'!$B$6:$C$15,'55 серия'!$B$6:$B$15=$C10)), )"),"") | BW10: =IFERROR(__xludf.DUMMYFUNCTION("IFNA(SUM(FILTER('56 серия'!$B$6:$C$15,'56 серия'!$B$6:$B$15=$C10)), )"),"") | BX10: =IFERROR(__xludf.DUMMYFUNCTION("IFNA(SUM(FILTER('57 серия'!$B$6:$C$15,'57 серия'!$B$6:$B$15=$C10)), )"),"") | BY10: =IFERROR(__xludf.DUMMYFUNCTION("IFNA(SUM(FILTER('58 серия'!$B$6:$C$15,'58 серия'!$B$6:$B$15=$C10)), )"),"") | BZ10: =IFERROR(__xludf.DUMMYFUNCTION("IFNA(SUM(FILTER('59 серия'!$B$6:$C$15,'59 серия'!$B$6:$B$15=C10)), )"),26.5) -> 26.5 | CA10: =IFERROR(__xludf.DUMMYFUNCTION("IFNA(SUM(FILTER('60 серия'!$B$6:$C$15,'60 серия'!$B$6:$B$15=$C10)), )"),"")
B11: =ROW()-6 -> 5 | C11: Астория | D11: ='Игроки статистика'!B9 -> 50 | E11: =SUM(T11:CAZ11)-R11-S11 -> 206 | F11: =IFERROR((((E11)/D11)*5), ) -> 20.6 | G11: =IFERROR(((I11+J11+K11)/D11), ) -> 2.82 | H11: =SUMIFS('Все игры'!C$3:C1011,'Все игры'!A$3:A1011,C11) -> 65 | I11: =E11-H11-J11-K11 -> 139 | J11: =SUMIFS('Все игры'!F$3:F1011,'Все игры'!A$3:A1011,C11) -> 0.5 | K11: =SUMIFS('Все игры'!G$3:G1011,'Все игры'!A$3:A1011,C11) -> 1.5 | L11: ='Игроки статистика'!G9 -> 3 | M11: =H11/2.5 -> 26 | N11: =SUM('Игроки статистика'!O9,'Игроки статистика'!Q9) -> 4 | O11: =SUM('Игроки статистика'!P9,'Игроки статистика'!R9) -> 5 | P11: =IFERROR(__xludf.DUMMYFUNCTION("IFNA(SUM(FILTER('Штрафы'!$D$5:$D1011,'Штрафы'!$C$5:$C1011=C11)), )"),"") | Q11: =IFERROR(__xludf.DUMMYFUNCTION("IFNA(SUM(FILTER('Штрафы'!$F$5:$F1011,'Штрафы'!$C$5:$C1011=C11)), )"),"") | T11: =IFERROR(__xludf.DUMMYFUNCTION("IFNA(SUM(FILTER('1 серия'!$B$6:$C$15,'1 серия'!$B$6:$B$15=C11)), )"),"") | U11: =IFERROR(__xludf.DUMMYFUNCTION("IFNA(SUM(FILTER('2 серия'!$B$6:$C$15,'2 серия'!$B$6:$B$15=C11)), ) "),"") | V11: =IFERROR(__xludf.DUMMYFUNCTION("IFNA(SUM(FILTER('3 серия'!$B$6:$C$15,'3 серия'!$B$6:$B$15=C11)), ) "),"") | W11: =IFERROR(__xludf.DUMMYFUNCTION("IFNA(SUM(FILTER('4 серия'!$B$6:$C$15,'4 серия'!$B$6:$B$15=C11)), )"),"") | X11: =IFERROR(__xludf.DUMMYFUNCTION("IFNA(SUM(FILTER('5 серия'!$B$6:$C$15,'5 серия'!$B$6:$B$15=C11)), )"),"") | Y11: =IFERROR(__xludf.DUMMYFUNCTION("IFNA(SUM(FILTER('6 серия'!$B$6:$C$15,'6 серия'!$B$6:$B$15=C11)), )"),"") | Z11: =IFERROR(__xludf.DUMMYFUNCTION("IFNA(SUM(FILTER('7 серия'!$B$6:$C$15,'7 серия'!$B$6:$B$15=C11)), )"),"") | AA11: =IFERROR(__xludf.DUMMYFUNCTION("IFNA(SUM(FILTER('8 серия'!$B$6:$C$15,'8 серия'!$B$6:$B$15=C11)), )"),"") | AB11: =IFERROR(__xludf.DUMMYFUNCTION("IFNA(SUM(FILTER('9 серия'!$B$7:$C$16,'9 серия'!$B$7:$B$16=C11)), )"),"") | AC11: =IFERROR(__xludf.DUMMYFUNCTION("IFNA(SUM(FILTER('10 серия'!$B$6:$C$15,'10 серия'!$B$6:$B$15=C11)), )"),"") | AD11: =IFERROR(__xludf.DUMMYFUNCTION("IFNA(SUM(FILTER('11 серия'!$B$6:$C$15,'11 серия'!$B$6:$B$15=C11)), )"),"") | AE11: =IFERROR(__xludf.DUMMYFUNCTION("IFNA(SUM(FILTER('12 серия'!$B$6:$C$15,'12 серия'!$B$6:$B$15=C11)), )"),"") | AF11: =IFERROR(__xludf.DUMMYFUNCTION("IFNA(SUM(FILTER('13 серия'!$B$6:$C$15,'13 серия'!$B$6:$B$15=C11)), )"),"") | AG11: =IFERROR(__xludf.DUMMYFUNCTION("IFNA(SUM(FILTER('14 серия'!$B$6:$C$15,'14 серия'!$B$6:$B$15=C11)), )"),"") | AH11: =IFERROR(__xludf.DUMMYFUNCTION("IFNA(SUM(FILTER('15 серия'!$B$6:$C$15,'15 серия'!$B$6:$B$15=C11)), )"),"") | AI11: =IFERROR(__xludf.DUMMYFUNCTION("IFNA(SUM(FILTER('16 серия'!$B$6:$C$15,'16 серия'!$B$6:$B$15=C11)), )"),"") | AJ11: =IFERROR(__xludf.DUMMYFUNCTION("IFNA(SUM(FILTER('17 серия'!$B$6:$C$15,'17 серия'!$B$6:$B$15=C11)), )"),17.75) -> 17.75 | AK11: =IFERROR(__xludf.DUMMYFUNCTION("IFNA(SUM(FILTER('18 серия'!$B$6:$C$15,'18 серия'!$B$6:$B$15=C11)), )"),19.5) -> 19.5 | AL11: =IFERROR(__xludf.DUMMYFUNCTION("IFNA(SUM(FILTER('19 серия'!$B$6:$C$15,'19 серия'!$B$6:$B$15=C11)), )"),11.25) -> 11.25 | AM11: =IFERROR(__xludf.DUMMYFUNCTION("IFNA(SUM(FILTER('20 серия'!$B$6:$C$15,'20 серия'!$B$6:$B$15=C11)), )"),23.0) -> 23 | AN11: =IFERROR(__xludf.DUMMYFUNCTION("IFNA(SUM(FILTER('21 серия'!$B$6:$C$15,'21 серия'!$B$6:$B$15=C11)), )"),"") | AO11: =IFERROR(__xludf.DUMMYFUNCTION("IFNA(SUM(FILTER('22 серия'!$B$6:$C$15,'22 серия'!$B$6:$B$15=C11)), )"),"") | AP11: =IFERROR(__xludf.DUMMYFUNCTION("IFNA(SUM(FILTER('23 серия'!$B$6:$C$15,'23 серия'!$B$6:$B$15=C11)), )"),"") | AQ11: =IFERROR(__xludf.DUMMYFUNCTION("IFNA(SUM(FILTER('24 серия'!$B$6:$C$15,'24 серия'!$B$6:$B$15=C11)), )"),"") | AR11: =IFERROR(__xludf.DUMMYFUNCTION("IFNA(SUM(FILTER('25 серия'!$B$6:$C$15,'25 серия'!$B$6:$B$15=C11)), )"),"") | AS11: =IFERROR(__xludf.DUMMYFUNCTION("IFNA(SUM(FILTER('26 серия'!$B$6:$C$15,'26 серия'!$B$6:$B$15=C11)), )"),"") | AT11: =IFERROR(__xludf.DUMMYFUNCTION("IFNA(SUM(FILTER('27 серия'!$B$6:$C$15,'27 серия'!$B$6:$B$15=C11)), )"),"") | AU11: =IFERROR(__xludf.DUMMYFUNCTION("IFNA(SUM(FILTER('28 серия'!$B$6:$C$15,'28 серия'!$B$6:$B$15=C11)), )"),"") | AV11: =IFERROR(__xludf.DUMMYFUNCTION("IFNA(SUM(FILTER('29 серия'!$B$6:$C$15,'29 серия'!$B$6:$B$15=C11)), )"),"") | AW11: =IFERROR(__xludf.DUMMYFUNCTION("IFNA(SUM(FILTER('30 серия'!$B$6:$C$15,'30 серия'!$B$6:$B$15=C11)), )"),"") | AX11: =IFERROR(__xludf.DUMMYFUNCTION("IFNA(SUM(FILTER('31 серия'!$B$6:$C$15,'31 серия'!$B$6:$B$15=C11)), )"),"") | AY11: =IFERROR(__xludf.DUMMYFUNCTION("IFNA(SUM(FILTER('32 серия'!$B$6:$C$15,'32 серия'!$B$6:$B$15=C11)), )"),"") | AZ11: =IFERROR(__xludf.DUMMYFUNCTION("IFNA(SUM(FILTER('33 серия'!$B$6:$C$15,'33 серия'!$B$6:$B$15=C11)), )"),"") | BA11: =IFERROR(__xludf.DUMMYFUNCTION("IFNA(SUM(FILTER('34 серия'!$B$6:$C$15,'34 серия'!$B$6:$B$15=C11)), )"),"") | BB11: =IFERROR(__xludf.DUMMYFUNCTION("IFNA(SUM(FILTER('35 серия'!$B$6:$C$15,'35 серия'!$B$6:$B$15=C11)), )"),"") | BC11: =IFERROR(__xludf.DUMMYFUNCTION("IFNA(SUM(FILTER('36 серия'!$B$6:$C$15,'36 серия'!$B$6:$B$15=C11)), )"),"") | BD11: =IFERROR(__xludf.DUMMYFUNCTION("IFNA(SUM(FILTER('37 серия'!$B$6:$C$15,'37 серия'!$B$6:$B$15=C11)), )"),"") | BE11: =IFERROR(__xludf.DUMMYFUNCTION("IFNA(SUM(FILTER('38 серия'!$B$6:$C$15,'38 серия'!$B$6:$B$15=C11)), )"),"") | BF11: =IFERROR(__xludf.DUMMYFUNCTION("IFNA(SUM(FILTER('39 серия'!$B$6:$C$15,'39 серия'!$B$6:$B$15=C11)), )"),"") | BG11: =IFERROR(__xludf.DUMMYFUNCTION("IFNA(SUM(FILTER('40 серия'!$B$6:$C$15,'40 серия'!$B$6:$B$15=C11)), )"),"") | BH11: =IFERROR(__xludf.DUMMYFUNCTION("IFNA(SUM(FILTER('41 серия'!$B$6:$C$15,'41 серия'!$B$6:$B$15=C11)), )"),"") | BI11: =IFERROR(__xludf.DUMMYFUNCTION("IFNA(SUM(FILTER('42 серия'!$B$6:$C$15,'42 серия'!$B$6:$B$15=C11)), )"),"") | BJ11: =IFERROR(__xludf.DUMMYFUNCTION("IFNA(SUM(FILTER('43 серия'!$B$6:$C$15,'43 серия'!$B$6:$B$15=C11)), )"),"") | BK11: =IFERROR(__xludf.DUMMYFUNCTION("IFNA(SUM(FILTER('44 серия'!$B$6:$C$15,'44 серия'!$B$6:$B$15=C11)), )"),"") | BL11: =IFERROR(__xludf.DUMMYFUNCTION("IFNA(SUM(FILTER('45 серия'!$B$6:$C$15,'45 серия'!$B$6:$B$15=C11)), )"),21.25) -> 21.25 | BM11: =IFERROR(__xludf.DUMMYFUNCTION("IFNA(SUM(FILTER('46 серия'!$B$6:$C$15,'46 серия'!$B$6:$B$15=C11)), )"),25.0) -> 25 | BN11: =IFERROR(__xludf.DUMMYFUNCTION("IFNA(SUM(FILTER('47 серия'!$B$6:$C$15,'47 серия'!$B$6:$B$15=C11)), )"),19.25) -> 19.25 | BO11: =IFERROR(__xludf.DUMMYFUNCTION("IFNA(SUM(FILTER('48 серия'!$B$6:$C$15,'48 серия'!$B$6:$B$15=$C11)), )"),"") | BP11: =IFERROR(__xludf.DUMMYFUNCTION("IFNA(SUM(FILTER('49 серия'!$B$6:$C$15,'49 серия'!$B$6:$B$15=$C11)), )"),"") | BQ11: =IFERROR(__xludf.DUMMYFUNCTION("IFNA(SUM(FILTER('50 серия'!$B$6:$C$15,'50 серия'!$B$6:$B$15=$C11)), )"),"") | BR11: =IFERROR(__xludf.DUMMYFUNCTION("IFNA(SUM(FILTER('51 серия'!$B$6:$C$15,'51 серия'!$B$6:$B$15=$C11)), )"),"") | BS11: =IFERROR(__xludf.DUMMYFUNCTION("IFNA(SUM(FILTER('52 серия'!$B$6:$C$15,'52 серия'!$B$6:$B$15=C11)), )"),"") | BT11: =IFERROR(__xludf.DUMMYFUNCTION("IFNA(SUM(FILTER('53 серия'!$B$6:$C$15,'53 серия'!$B$6:$B$15=$C11)), )"),"") | BU11: =IFERROR(__xludf.DUMMYFUNCTION("IFNA(SUM(FILTER('54 серия'!$B$6:$C$15,'54 серия'!$B$6:$B$15=$C11)), )"),17.25) -> 17.25 | BV11: =IFERROR(__xludf.DUMMYFUNCTION("IFNA(SUM(FILTER('55 серия'!$B$6:$C$15,'55 серия'!$B$6:$B$15=$C11)), )"),25.5) -> 25.5 | BW11: =IFERROR(__xludf.DUMMYFUNCTION("IFNA(SUM(FILTER('56 серия'!$B$6:$C$15,'56 серия'!$B$6:$B$15=$C11)), )"),26.25) -> 26.25 | BX11: =IFERROR(__xludf.DUMMYFUNCTION("IFNA(SUM(FILTER('57 серия'!$B$6:$C$15,'57 серия'!$B$6:$B$15=$C11)), )"),"") | BY11: =IFERROR(__xludf.DUMMYFUNCTION("IFNA(SUM(FILTER('58 серия'!$B$6:$C$15,'58 серия'!$B$6:$B$15=$C11)), )"),"") | BZ11: =IFERROR(__xludf.DUMMYFUNCTION("IFNA(SUM(FILTER('59 серия'!$B$6:$C$15,'59 серия'!$B$6:$B$15=C11)), )"),"") | CA11: =IFERROR(__xludf.DUMMYFUNCTION("IFNA(SUM(FILTER('60 серия'!$B$6:$C$15,'60 серия'!$B$6:$B$15=$C11)), )"),"")
B12: =ROW()-6 -> 6 | C12: Аш | D12: ='Игроки статистика'!B10 -> 50 | E12: =SUM(T12:CAZ12)-R12-S12 -> 194.75 | F12: =IFERROR((((E12)/D12)*5), ) -> 19.475 | G12: =IFERROR(((I12+J12+K12)/D12), ) -> 2.745 | H12: =SUMIFS('Все игры'!C$3:C1011,'Все игры'!A$3:A1011,C12) -> 57.5 | I12: =E12-H12-J12-K12 -> 135.75 | J12: =SUMIFS('Все игры'!F$3:F1011,'Все игры'!A$3:A1011,C12) -> 0.5 | K12: =SUMIFS('Все игры'!G$3:G1011,'Все игры'!A$3:A1011,C12) -> 1 | L12: ='Игроки статистика'!G10 -> 2 | M12: =H12/2.5 -> 23 | N12: =SUM('Игроки статистика'!O10,'Игроки статистика'!Q10) -> 5 | O12: =SUM('Игроки статистика'!P10,'Игроки статистика'!R10) -> 4 | P12: =IFERROR(__xludf.DUMMYFUNCTION("IFNA(SUM(FILTER('Штрафы'!$D$5:$D1011,'Штрафы'!$C$5:$C1011=C12)), )"),"") | Q12: =IFERROR(__xludf.DUMMYFUNCTION("IFNA(SUM(FILTER('Штрафы'!$F$5:$F1011,'Штрафы'!$C$5:$C1011=C12)), )"),"") | T12: =IFERROR(__xludf.DUMMYFUNCTION("IFNA(SUM(FILTER('1 серия'!$B$6:$C$15,'1 серия'!$B$6:$B$15=C12)), )"),"") | U12: =IFERROR(__xludf.DUMMYFUNCTION("IFNA(SUM(FILTER('2 серия'!$B$6:$C$15,'2 серия'!$B$6:$B$15=C12)), ) "),"") | V12: =IFERROR(__xludf.DUMMYFUNCTION("IFNA(SUM(FILTER('3 серия'!$B$6:$C$15,'3 серия'!$B$6:$B$15=C12)), ) "),"") | W12: =IFERROR(__xludf.DUMMYFUNCTION("IFNA(SUM(FILTER('4 серия'!$B$6:$C$15,'4 серия'!$B$6:$B$15=C12)), )"),"") | X12: =IFERROR(__xludf.DUMMYFUNCTION("IFNA(SUM(FILTER('5 серия'!$B$6:$C$15,'5 серия'!$B$6:$B$15=C12)), )"),"") | Y12: =IFERROR(__xludf.DUMMYFUNCTION("IFNA(SUM(FILTER('6 серия'!$B$6:$C$15,'6 серия'!$B$6:$B$15=C12)), )"),"") | Z12: =IFERROR(__xludf.DUMMYFUNCTION("IFNA(SUM(FILTER('7 серия'!$B$6:$C$15,'7 серия'!$B$6:$B$15=C12)), )"),"") | AA12: =IFERROR(__xludf.DUMMYFUNCTION("IFNA(SUM(FILTER('8 серия'!$B$6:$C$15,'8 серия'!$B$6:$B$15=C12)), )"),"") | AB12: =IFERROR(__xludf.DUMMYFUNCTION("IFNA(SUM(FILTER('9 серия'!$B$7:$C$16,'9 серия'!$B$7:$B$16=C12)), )"),"") | AC12: =IFERROR(__xludf.DUMMYFUNCTION("IFNA(SUM(FILTER('10 серия'!$B$6:$C$15,'10 серия'!$B$6:$B$15=C12)), )"),"") | AD12: =IFERROR(__xludf.DUMMYFUNCTION("IFNA(SUM(FILTER('11 серия'!$B$6:$C$15,'11 серия'!$B$6:$B$15=C12)), )"),"") | AE12: =IFERROR(__xludf.DUMMYFUNCTION("IFNA(SUM(FILTER('12 серия'!$B$6:$C$15,'12 серия'!$B$6:$B$15=C12)), )"),"") | AF12: =IFERROR(__xludf.DUMMYFUNCTION("IFNA(SUM(FILTER('13 серия'!$B$6:$C$15,'13 серия'!$B$6:$B$15=C12)), )"),"") | AG12: =IFERROR(__xludf.DUMMYFUNCTION("IFNA(SUM(FILTER('14 серия'!$B$6:$C$15,'14 серия'!$B$6:$B$15=C12)), )"),"") | AH12: =IFERROR(__xludf.DUMMYFUNCTION("IFNA(SUM(FILTER('15 серия'!$B$6:$C$15,'15 серия'!$B$6:$B$15=C12)), )"),"") | AI12: =IFERROR(__xludf.DUMMYFUNCTION("IFNA(SUM(FILTER('16 серия'!$B$6:$C$15,'16 серия'!$B$6:$B$15=C12)), )"),"") | AJ12: =IFERROR(__xludf.DUMMYFUNCTION("IFNA(SUM(FILTER('17 серия'!$B$6:$C$15,'17 серия'!$B$6:$B$15=C12)), )"),17.75) -> 17.75 | AK12: =IFERROR(__xludf.DUMMYFUNCTION("IFNA(SUM(FILTER('18 серия'!$B$6:$C$15,'18 серия'!$B$6:$B$15=C12)), )"),23.25) -> 23.25 | AL12: =IFERROR(__xludf.DUMMYFUNCTION("IFNA(SUM(FILTER('19 серия'!$B$6:$C$15,'19 серия'!$B$6:$B$15=C12)), )"),19.5) -> 19.5 | AM12: =IFERROR(__xludf.DUMMYFUNCTION("IFNA(SUM(FILTER('20 серия'!$B$6:$C$15,'20 серия'!$B$6:$B$15=C12)), )"),"") | AN12: =IFERROR(__xludf.DUMMYFUNCTION("IFNA(SUM(FILTER('21 серия'!$B$6:$C$15,'21 серия'!$B$6:$B$15=C12)), )"),"") | AO12: =IFERROR(__xludf.DUMMYFUNCTION("IFNA(SUM(FILTER('22 серия'!$B$6:$C$15,'22 серия'!$B$6:$B$15=C12)), )"),"") | AP12: =IFERROR(__xludf.DUMMYFUNCTION("IFNA(SUM(FILTER('23 серия'!$B$6:$C$15,'23 серия'!$B$6:$B$15=C12)), )"),"") | AQ12: =IFERROR(__xludf.DUMMYFUNCTION("IFNA(SUM(FILTER('24 серия'!$B$6:$C$15,'24 серия'!$B$6:$B$15=C12)), )"),"") | AR12: =IFERROR(__xludf.DUMMYFUNCTION("IFNA(SUM(FILTER('25 серия'!$B$6:$C$15,'25 серия'!$B$6:$B$15=C12)), )"),"") | AS12: =IFERROR(__xludf.DUMMYFUNCTION("IFNA(SUM(FILTER('26 серия'!$B$6:$C$15,'26 серия'!$B$6:$B$15=C12)), )"),"") | AT12: =IFERROR(__xludf.DUMMYFUNCTION("IFNA(SUM(FILTER('27 серия'!$B$6:$C$15,'27 серия'!$B$6:$B$15=C12)), )"),"") | AU12: =IFERROR(__xludf.DUMMYFUNCTION("IFNA(SUM(FILTER('28 серия'!$B$6:$C$15,'28 серия'!$B$6:$B$15=C12)), )"),21.0) -> 21 | AV12: =IFERROR(__xludf.DUMMYFUNCTION("IFNA(SUM(FILTER('29 серия'!$B$6:$C$15,'29 серия'!$B$6:$B$15=C12)), )"),27.0) -> 27 | AW12: =IFERROR(__xludf.DUMMYFUNCTION("IFNA(SUM(FILTER('30 серия'!$B$6:$C$15,'30 серия'!$B$6:$B$15=C12)), )"),17.25) -> 17.25 | AX12: =IFERROR(__xludf.DUMMYFUNCTION("IFNA(SUM(FILTER('31 серия'!$B$6:$C$15,'31 серия'!$B$6:$B$15=C12)), )"),"") | AY12: =IFERROR(__xludf.DUMMYFUNCTION("IFNA(SUM(FILTER('32 серия'!$B$6:$C$15,'32 серия'!$B$6:$B$15=C12)), )"),"") | AZ12: =IFERROR(__xludf.DUMMYFUNCTION("IFNA(SUM(FILTER('33 серия'!$B$6:$C$15,'33 серия'!$B$6:$B$15=C12)), )"),"") | BA12: =IFERROR(__xludf.DUMMYFUNCTION("IFNA(SUM(FILTER('34 серия'!$B$6:$C$15,'34 серия'!$B$6:$B$15=C12)), )"),"") | BB12: =IFERROR(__xludf.DUMMYFUNCTION("IFNA(SUM(FILTER('35 серия'!$B$6:$C$15,'35 серия'!$B$6:$B$15=C12)), )"),"") | BC12: =IFERROR(__xludf.DUMMYFUNCTION("IFNA(SUM(FILTER('36 серия'!$B$6:$C$15,'36 серия'!$B$6:$B$15=C12)), )"),"") | BD12: =IFERROR(__xludf.DUMMYFUNCTION("IFNA(SUM(FILTER('37 серия'!$B$6:$C$15,'37 серия'!$B$6:$B$15=C12)), )"),"") | BE12: =IFERROR(__xludf.DUMMYFUNCTION("IFNA(SUM(FILTER('38 серия'!$B$6:$C$15,'38 серия'!$B$6:$B$15=C12)), )"),17.75) -> 17.75 | BF12: =IFERROR(__xludf.DUMMYFUNCTION("IFNA(SUM(FILTER('39 серия'!$B$6:$C$15,'39 серия'!$B$6:$B$15=C12)), )"),15.75) -> 15.75 | BG12: =IFERROR(__xludf.DUMMYFUNCTION("IFNA(SUM(FILTER('40 серия'!$B$6:$C$15,'40 серия'!$B$6:$B$15=C12)), )"),13.75) -> 13.75 | BH12: =IFERROR(__xludf.DUMMYFUNCTION("IFNA(SUM(FILTER('41 серия'!$B$6:$C$15,'41 серия'!$B$6:$B$15=C12)), )"),21.75) -> 21.75 | BI12: =IFERROR(__xludf.DUMMYFUNCTION("IFNA(SUM(FILTER('42 серия'!$B$6:$C$15,'42 серия'!$B$6:$B$15=C12)), )"),"") | BJ12: =IFERROR(__xludf.DUMMYFUNCTION("IFNA(SUM(FILTER('43 серия'!$B$6:$C$15,'43 серия'!$B$6:$B$15=C12)), )"),"") | BK12: =IFERROR(__xludf.DUMMYFUNCTION("IFNA(SUM(FILTER('44 серия'!$B$6:$C$15,'44 серия'!$B$6:$B$15=C12)), )"),"") | BL12: =IFERROR(__xludf.DUMMYFUNCTION("IFNA(SUM(FILTER('45 серия'!$B$6:$C$15,'45 серия'!$B$6:$B$15=C12)), )"),"") | BM12: =IFERROR(__xludf.DUMMYFUNCTION("IFNA(SUM(FILTER('46 серия'!$B$6:$C$15,'46 серия'!$B$6:$B$15=C12)), )"),"") | BN12: =IFERROR(__xludf.DUMMYFUNCTION("IFNA(SUM(FILTER('47 серия'!$B$6:$C$15,'47 серия'!$B$6:$B$15=C12)), )"),"") | BO12: =IFERROR(__xludf.DUMMYFUNCTION("IFNA(SUM(FILTER('48 серия'!$B$6:$C$15,'48 серия'!$B$6:$B$15=$C12)), )"),"") | BP12: =IFERROR(__xludf.DUMMYFUNCTION("IFNA(SUM(FILTER('49 серия'!$B$6:$C$15,'49 серия'!$B$6:$B$15=$C12)), )"),"") | BQ12: =IFERROR(__xludf.DUMMYFUNCTION("IFNA(SUM(FILTER('50 серия'!$B$6:$C$15,'50 серия'!$B$6:$B$15=$C12)), )"),"") | BR12: =IFERROR(__xludf.DUMMYFUNCTION("IFNA(SUM(FILTER('51 серия'!$B$6:$C$15,'51 серия'!$B$6:$B$15=$C12)), )"),"") | BS12: =IFERROR(__xludf.DUMMYFUNCTION("IFNA(SUM(FILTER('52 серия'!$B$6:$C$15,'52 серия'!$B$6:$B$15=C12)), )"),"") | BT12: =IFERROR(__xludf.DUMMYFUNCTION("IFNA(SUM(FILTER('53 серия'!$B$6:$C$15,'53 серия'!$B$6:$B$15=$C12)), )"),"") | BU12: =IFERROR(__xludf.DUMMYFUNCTION("IFNA(SUM(FILTER('54 серия'!$B$6:$C$15,'54 серия'!$B$6:$B$15=$C12)), )"),"") | BV12: =IFERROR(__xludf.DUMMYFUNCTION("IFNA(SUM(FILTER('55 серия'!$B$6:$C$15,'55 серия'!$B$6:$B$15=$C12)), )"),"") | BW12: =IFERROR(__xludf.DUMMYFUNCTION("IFNA(SUM(FILTER('56 серия'!$B$6:$C$15,'56 серия'!$B$6:$B$15=$C12)), )"),"") | BX12: =IFERROR(__xludf.DUMMYFUNCTION("IFNA(SUM(FILTER('57 серия'!$B$6:$C$15,'57 серия'!$B$6:$B$15=$C12)), )"),"") | BY12: =IFERROR(__xludf.DUMMYFUNCTION("IFNA(SUM(FILTER('58 серия'!$B$6:$C$15,'58 серия'!$B$6:$B$15=$C12)), )"),"") | BZ12: =IFERROR(__xludf.DUMMYFUNCTION("IFNA(SUM(FILTER('59 серия'!$B$6:$C$15,'59 серия'!$B$6:$B$15=C12)), )"),"") | CA12: =IFERROR(__xludf.DUMMYFUNCTION("IFNA(SUM(FILTER('60 серия'!$B$6:$C$15,'60 серия'!$B$6:$B$15=$C12)), )"),"")
B13: =ROW()-6 -> 7 | C13: Бамблби | D13: ='Игроки статистика'!B11 -> 50 | E13: =SUM(T13:CAZ13)-R13-S13 -> 162.5 | F13: =IFERROR((((E13)/D13)*5), ) -> 16.25 | G13: =IFERROR(((I13+J13+K13)/D13), ) -> 2.5 | H13: =SUMIFS('Все игры'!C$3:C1011,'Все игры'!A$3:A1011,C13) -> 37.5 | I13: =E13-H13-J13-K13 -> 122.5 | J13: =SUMIFS('Все игры'!F$3:F1011,'Все игры'!A$3:A1011,C13) -> 1 | K13: =SUMIFS('Все игры'!G$3:G1011,'Все игры'!A$3:A1011,C13) -> 1.5 | L13: ='Игроки статистика'!G11 -> 3 | M13: =H13/2.5 -> 15 | N13: =SUM('Игроки статистика'!O11,'Игроки статистика'!Q11) -> 4 | O13: =SUM('Игроки статистика'!P11,'Игроки статистика'!R11) -> 6 | P13: =IFERROR(__xludf.DUMMYFUNCTION("IFNA(SUM(FILTER('Штрафы'!$D$5:$D1011,'Штрафы'!$C$5:$C1011=C13)), )"),"") | Q13: =IFERROR(__xludf.DUMMYFUNCTION("IFNA(SUM(FILTER('Штрафы'!$F$5:$F1011,'Штрафы'!$C$5:$C1011=C13)), )"),"") | T13: =IFERROR(__xludf.DUMMYFUNCTION("IFNA(SUM(FILTER('1 серия'!$B$6:$C$15,'1 серия'!$B$6:$B$15=C13)), )"),"") | U13: =IFERROR(__xludf.DUMMYFUNCTION("IFNA(SUM(FILTER('2 серия'!$B$6:$C$15,'2 серия'!$B$6:$B$15=C13)), ) "),14.25) -> 14.25 | V13: =IFERROR(__xludf.DUMMYFUNCTION("IFNA(SUM(FILTER('3 серия'!$B$6:$C$15,'3 серия'!$B$6:$B$15=C13)), ) "),"") | W13: =IFERROR(__xludf.DUMMYFUNCTION("IFNA(SUM(FILTER('4 серия'!$B$6:$C$15,'4 серия'!$B$6:$B$15=C13)), )"),16.5) -> 16.5 | X13: =IFERROR(__xludf.DUMMYFUNCTION("IFNA(SUM(FILTER('5 серия'!$B$6:$C$15,'5 серия'!$B$6:$B$15=C13)), )"),"") | Y13: =IFERROR(__xludf.DUMMYFUNCTION("IFNA(SUM(FILTER('6 серия'!$B$6:$C$15,'6 серия'!$B$6:$B$15=C13)), )"),15.75) -> 15.75 | Z13: =IFERROR(__xludf.DUMMYFUNCTION("IFNA(SUM(FILTER('7 серия'!$B$6:$C$15,'7 серия'!$B$6:$B$15=C13)), )"),"") | AA13: =IFERROR(__xludf.DUMMYFUNCTION("IFNA(SUM(FILTER('8 серия'!$B$6:$C$15,'8 серия'!$B$6:$B$15=C13)), )"),"") | AB13: =IFERROR(__xludf.DUMMYFUNCTION("IFNA(SUM(FILTER('9 серия'!$B$7:$C$16,'9 серия'!$B$7:$B$16=C13)), )"),"") | AC13: =IFERROR(__xludf.DUMMYFUNCTION("IFNA(SUM(FILTER('10 серия'!$B$6:$C$15,'10 серия'!$B$6:$B$15=C13)), )"),15.75) -> 15.75 | AD13: =IFERROR(__xludf.DUMMYFUNCTION("IFNA(SUM(FILTER('11 серия'!$B$6:$C$15,'11 серия'!$B$6:$B$15=C13)), )"),"") | AE13: =IFERROR(__xludf.DUMMYFUNCTION("IFNA(SUM(FILTER('12 серия'!$B$6:$C$15,'12 серия'!$B$6:$B$15=C13)), )"),"") | AF13: =IFERROR(__xludf.DUMMYFUNCTION("IFNA(SUM(FILTER('13 серия'!$B$6:$C$15,'13 серия'!$B$6:$B$15=C13)), )"),"") | AG13: =IFERROR(__xludf.DUMMYFUNCTION("IFNA(SUM(FILTER('14 серия'!$B$6:$C$15,'14 серия'!$B$6:$B$15=C13)), )"),"") | AH13: =IFERROR(__xludf.DUMMYFUNCTION("IFNA(SUM(FILTER('15 серия'!$B$6:$C$15,'15 серия'!$B$6:$B$15=C13)), )"),"") | AI13: =IFERROR(__xludf.DUMMYFUNCTION("IFNA(SUM(FILTER('16 серия'!$B$6:$C$15,'16 серия'!$B$6:$B$15=C13)), )"),"") | AJ13: =IFERROR(__xludf.DUMMYFUNCTION("IFNA(SUM(FILTER('17 серия'!$B$6:$C$15,'17 серия'!$B$6:$B$15=C13)), )"),"") | AK13: =IFERROR(__xludf.DUMMYFUNCTION("IFNA(SUM(FILTER('18 серия'!$B$6:$C$15,'18 серия'!$B$6:$B$15=C13)), )"),"") | AL13: =IFERROR(__xludf.DUMMYFUNCTION("IFNA(SUM(FILTER('19 серия'!$B$6:$C$15,'19 серия'!$B$6:$B$15=C13)), )"),"") | AM13: =IFERROR(__xludf.DUMMYFUNCTION("IFNA(SUM(FILTER('20 серия'!$B$6:$C$15,'20 серия'!$B$6:$B$15=C13)), )"),"") | AN13: =IFERROR(__xludf.DUMMYFUNCTION("IFNA(SUM(FILTER('21 серия'!$B$6:$C$15,'21 серия'!$B$6:$B$15=C13)), )"),"") | AO13: =IFERROR(__xludf.DUMMYFUNCTION("IFNA(SUM(FILTER('22 серия'!$B$6:$C$15,'22 серия'!$B$6:$B$15=C13)), )"),14.25) -> 14.25 | AP13: =IFERROR(__xludf.DUMMYFUNCTION("IFNA(SUM(FILTER('23 серия'!$B$6:$C$15,'23 серия'!$B$6:$B$15=C13)), )"),"") | AQ13: =IFERROR(__xludf.DUMMYFUNCTION("IFNA(SUM(FILTER('24 серия'!$B$6:$C$15,'24 серия'!$B$6:$B$15=C13)), )"),"") | AR13: =IFERROR(__xludf.DUMMYFUNCTION("IFNA(SUM(FILTER('25 серия'!$B$6:$C$15,'25 серия'!$B$6:$B$15=C13)), )"),"") | AS13: =IFERROR(__xludf.DUMMYFUNCTION("IFNA(SUM(FILTER('26 серия'!$B$6:$C$15,'26 серия'!$B$6:$B$15=C13)), )"),"") | AT13: =IFERROR(__xludf.DUMMYFUNCTION("IFNA(SUM(FILTER('27 серия'!$B$6:$C$15,'27 серия'!$B$6:$B$15=C13)), )"),"") | AU13: =IFERROR(__xludf.DUMMYFUNCTION("IFNA(SUM(FILTER('28 серия'!$B$6:$C$15,'28 серия'!$B$6:$B$15=C13)), )"),19.25) -> 19.25 | AV13: =IFERROR(__xludf.DUMMYFUNCTION("IFNA(SUM(FILTER('29 серия'!$B$6:$C$15,'29 серия'!$B$6:$B$15=C13)), )"),"") | AW13: =IFERROR(__xludf.DUMMYFUNCTION("IFNA(SUM(FILTER('30 серия'!$B$6:$C$15,'30 серия'!$B$6:$B$15=C13)), )"),"") | AX13: =IFERROR(__xludf.DUMMYFUNCTION("IFNA(SUM(FILTER('31 серия'!$B$6:$C$15,'31 серия'!$B$6:$B$15=C13)), )"),"") | AY13: =IFERROR(__xludf.DUMMYFUNCTION("IFNA(SUM(FILTER('32 серия'!$B$6:$C$15,'32 серия'!$B$6:$B$15=C13)), )"),"") | AZ13: =IFERROR(__xludf.DUMMYFUNCTION("IFNA(SUM(FILTER('33 серия'!$B$6:$C$15,'33 серия'!$B$6:$B$15=C13)), )"),"") | BA13: =IFERROR(__xludf.DUMMYFUNCTION("IFNA(SUM(FILTER('34 серия'!$B$6:$C$15,'34 серия'!$B$6:$B$15=C13)), )"),"") | BB13: =IFERROR(__xludf.DUMMYFUNCTION("IFNA(SUM(FILTER('35 серия'!$B$6:$C$15,'35 серия'!$B$6:$B$15=C13)), )"),"") | BC13: =IFERROR(__xludf.DUMMYFUNCTION("IFNA(SUM(FILTER('36 серия'!$B$6:$C$15,'36 серия'!$B$6:$B$15=C13)), )"),23.25) -> 23.25 | BD13: =IFERROR(__xludf.DUMMYFUNCTION("IFNA(SUM(FILTER('37 серия'!$B$6:$C$15,'37 серия'!$B$6:$B$15=C13)), )"),"") | BE13: =IFERROR(__xludf.DUMMYFUNCTION("IFNA(SUM(FILTER('38 серия'!$B$6:$C$15,'38 серия'!$B$6:$B$15=C13)), )"),"") | BF13: =IFERROR(__xludf.DUMMYFUNCTION("IFNA(SUM(FILTER('39 серия'!$B$6:$C$15,'39 серия'!$B$6:$B$15=C13)), )"),"") | BG13: =IFERROR(__xludf.DUMMYFUNCTION("IFNA(SUM(FILTER('40 серия'!$B$6:$C$15,'40 серия'!$B$6:$B$15=C13)), )"),13.75) -> 13.75 | BH13: =IFERROR(__xludf.DUMMYFUNCTION("IFNA(SUM(FILTER('41 серия'!$B$6:$C$15,'41 серия'!$B$6:$B$15=C13)), )"),"") | BI13: =IFERROR(__xludf.DUMMYFUNCTION("IFNA(SUM(FILTER('42 серия'!$B$6:$C$15,'42 серия'!$B$6:$B$15=C13)), )"),"") | BJ13: =IFERROR(__xludf.DUMMYFUNCTION("IFNA(SUM(FILTER('43 серия'!$B$6:$C$15,'43 серия'!$B$6:$B$15=C13)), )"),"") | BK13: =IFERROR(__xludf.DUMMYFUNCTION("IFNA(SUM(FILTER('44 серия'!$B$6:$C$15,'44 серия'!$B$6:$B$15=C13)), )"),"") | BL13: =IFERROR(__xludf.DUMMYFUNCTION("IFNA(SUM(FILTER('45 серия'!$B$6:$C$15,'45 серия'!$B$6:$B$15=C13)), )"),"") | BM13: =IFERROR(__xludf.DUMMYFUNCTION("IFNA(SUM(FILTER('46 серия'!$B$6:$C$15,'46 серия'!$B$6:$B$15=C13)), )"),"") | BN13: =IFERROR(__xludf.DUMMYFUNCTION("IFNA(SUM(FILTER('47 серия'!$B$6:$C$15,'47 серия'!$B$6:$B$15=C13)), )"),"") | BO13: =IFERROR(__xludf.DUMMYFUNCTION("IFNA(SUM(FILTER('48 серия'!$B$6:$C$15,'48 серия'!$B$6:$B$15=$C13)), )"),"") | BP13: =IFERROR(__xludf.DUMMYFUNCTION("IFNA(SUM(FILTER('49 серия'!$B$6:$C$15,'49 серия'!$B$6:$B$15=$C13)), )"),"") | BQ13: =IFERROR(__xludf.DUMMYFUNCTION("IFNA(SUM(FILTER('50 серия'!$B$6:$C$15,'50 серия'!$B$6:$B$15=$C13)), )"),"") | BR13: =IFERROR(__xludf.DUMMYFUNCTION("IFNA(SUM(FILTER('51 серия'!$B$6:$C$15,'51 серия'!$B$6:$B$15=$C13)), )"),"") | BS13: =IFERROR(__xludf.DUMMYFUNCTION("IFNA(SUM(FILTER('52 серия'!$B$6:$C$15,'52 серия'!$B$6:$B$15=C13)), )"),"") | BT13: =IFERROR(__xludf.DUMMYFUNCTION("IFNA(SUM(FILTER('53 серия'!$B$6:$C$15,'53 серия'!$B$6:$B$15=$C13)), )"),"") | BU13: =IFERROR(__xludf.DUMMYFUNCTION("IFNA(SUM(FILTER('54 серия'!$B$6:$C$15,'54 серия'!$B$6:$B$15=$C13)), )"),"") | BV13: =IFERROR(__xludf.DUMMYFUNCTION("IFNA(SUM(FILTER('55 серия'!$B$6:$C$15,'55 серия'!$B$6:$B$15=$C13)), )"),"") | BW13: =IFERROR(__xludf.DUMMYFUNCTION("IFNA(SUM(FILTER('56 серия'!$B$6:$C$15,'56 серия'!$B$6:$B$15=$C13)), )"),"") | BX13: =IFERROR(__xludf.DUMMYFUNCTION("IFNA(SUM(FILTER('57 серия'!$B$6:$C$15,'57 серия'!$B$6:$B$15=$C13)), )"),14.0) -> 14 | BY13: =IFERROR(__xludf.DUMMYFUNCTION("IFNA(SUM(FILTER('58 серия'!$B$6:$C$15,'58 серия'!$B$6:$B$15=$C13)), )"),"") | BZ13: =IFERROR(__xludf.DUMMYFUNCTION("IFNA(SUM(FILTER('59 серия'!$B$6:$C$15,'59 серия'!$B$6:$B$15=C13)), )"),15.75) -> 15.75 | CA13: =IFERROR(__xludf.DUMMYFUNCTION("IFNA(SUM(FILTER('60 серия'!$B$6:$C$15,'60 серия'!$B$6:$B$15=$C13)), )"),"")
